Workbook

Sheet Summary
A1: Another Home — Financial Model Summary (for Pitchdeck)
A2: Team 7 · Intro to Game Planning 2026-2 · All values USD · Everything here is calculated — edit the Assumptions sheet
A4: Pricing (Price slide) | B4: Value
A5: Another Home — Steam (PC / Steam Deck) | B5: =Assumptions!$D$7 -> 9.99
A6: Furniture DLC pack | B6: =Assumptions!$D$12 -> 2.99
A7: Original Soundtrack | B7: =Assumptions!$D$13 -> 4.99
A8: Browser version on itch.io | B8: Free / name your price
A9: Production budget | B9: =Assumptions!$D$5 -> 75000
A10: Planned development + launch cost | B10: ='Development Cost'!$F$25 -> 74580
A12: Scenario comparison (Gross Revenue & Targets slides) | B12: Low | C12: Base | D12: High | E12: Unit
A13: Wishlists at launch | B13: =Assumptions!$C$22 -> 8000 | C13: =Assumptions!$D$22 -> 25000 | D13: =Assumptions!$E$22 -> 60000 | E13: wishlists
A14: Steam copies — Year 1 | B14: =Revenue!C5 -> 3200 | C14: =Revenue!C17 -> 15000 | D14: =Revenue!C29 -> 54000 | E14: copies
A15: Steam copies — 3 years | B15: =Revenue!F5 -> 4880 | C15: =Revenue!F17 -> 27000 | D15: =Revenue!F29 -> 109080 | E15: copies
A16: Gross revenue — Year 1 | B16: =Revenue!C11 -> 23694.56 | C16: =Revenue!C23 -> 113365.75 | D16: =Revenue!C35 -> 420262.7 | E16: USD
A17: Gross revenue — Year 2 | B17: =Revenue!D11 -> 8943.096 | C17: =Revenue!D23 -> 57932.875 | D17: =Revenue!D35 -> 254157.62 | E17: USD
A18: Gross revenue — Year 3 | B18: =Revenue!E11 -> 4971.548 | C18: =Revenue!E23 -> 35759.725 | D18: =Revenue!E35 -> 179410.33 | E18: USD
A19: Gross revenue — 3 years total | B19: =Revenue!F11 -> 37609.204 | C19: =Revenue!F23 -> 207058.35 | D19: =Revenue!F35 -> 853830.65 | E19: USD
A20: Net revenue — 3 years total | B20: =Revenue!F14 -> 26926.443 | C20: =Revenue!F26 -> 146440.85 | D20: =Revenue!F38 -> 600681.46 | E20: USD
A21: Net profit incl. development — 3 years | B21: ='P&L & Break-even'!F13 -> -96892.176 | C21: ='P&L & Break-even'!F28 -> 12936.761 | D21: ='P&L & Break-even'!F43 -> 421753.31 | E21: USD
A22: ROI after 3 years | B22: ='P&L & Break-even'!B16 -> -1.299171 | C22: ='P&L & Break-even'!B31 -> 0.17346152 | D22: ='P&L & Break-even'!B46 -> 5.6550457 | E22: %
A23: NPV of 3 years | B23: ='P&L & Break-even'!B17 -> -91247.426 | C23: ='P&L & Break-even'!B32 -> -50.787589 | D23: ='P&L & Break-even'!B47 -> 336625.97 | E23: USD
A24: Break-even | B24: ='P&L & Break-even'!B15 -> After Year 3 | C24: ='P&L & Break-even'!B30 -> Year 2 | D24: ='P&L & Break-even'!B45 -> Year 1
A26: Revenue mix — Base, 3 years | B26: USD | C26: % of gross
A27: Game sales (Steam) | B27: =Revenue!F19 -> 179370.45 | C27: =IF($B$31=0,0,B27/$B$31) -> 0.86627972
A28: Furniture DLC | B28: =Revenue!F20 -> 16146 | C28: =IF($B$31=0,0,B28/$B$31) -> 0.077978019
A29: Soundtrack | B29: =Revenue!F21 -> 4041.9 | C29: =IF($B$31=0,0,B29/$B$31) -> 0.019520584
A30: itch.io browser tips | B30: =Revenue!F22 -> 7500 | C30: =IF($B$31=0,0,B30/$B$31) -> 0.036221674
A31: Total gross | B31: =SUM(B27:B30) -> 207058.35 | C31: =IF($B$31=0,0,B31/$B$31) -> 1
A33: Budget split (Development Cost slide) | B33: USD | C33: % of budget
A34: Team (personnel) | B34: ='Development Cost'!F10 -> 53800 | C34: ='Development Cost'!G10 -> 0.71733333
A35: Tools, legal & marketing | B35: ='Development Cost'!F20 -> 14000 | C35: ='Development Cost'!G20 -> 0.18666667
A36: Contingency | B36: ='Development Cost'!F23 -> 6780 | C36: ='Development Cost'!G23 -> 0.0904

Sheet Assumptions
A1: Another Home — Key Assumptions (edit blue cells only)
A2: Blue = input · Yellow = key assumption to defend in the pitch · All money in USD
A4: General parameter | B4: Unit | D4: Value | F4: Note / source
A5: Production budget | B5: USD | D5: 75000 | F5: Course sheet 'List of Groups', Team 7
A6: Development duration | B6: months | D6: 10 | F6: See Roadmap
A7: Steam base price | B7: USD | D7: 9.99 | F7: Cozy sandbox builders: Townscaper ≈ $6, Tiny Glade ≈ $15
A8: Average discount incl. sales & regional pricing | B8: % | D8: 0.3 | F8: Assumption: indie games sell much of their volume on sale
A9: Refund rate | B9: % | D9: 0.05 | F9: Assumption: typical 3–8% for small indie titles
A10: Steam revenue share | B10: % | D10: 0.3 | F10: Steam standard 30% below $10M revenue
A11: itch.io revenue share | B11: % | D11: 0.1 | F11: itch.io default open revenue share 10%
A12: Furniture DLC pack price | B12: USD | D12: 2.99 | F12: Assumption: cosmetic pack (e.g. 'Autumn Cabin', 'Tiny Café')
A13: Soundtrack price | B13: USD | D13: 4.99 | F13: Assumption: typical indie OST price
A14: Soundtrack attach rate | B14: % | D14: 0.03 | F14: Assumption
A15: Live-ops: monthly furniture drops, per year | B15: USD/yr | D15: 12000 | F15: Keeps the original dev's 'new furniture every month' promise
A16: Ongoing marketing per year | B16: USD/yr | D16: 4000 | F16: Creators, seasonal sales assets
... A19: Discount rate (NPV) | B19: % | D19: 0.12 | F19: Assumption for a small risky indie project
A21: Scenario parameter | B21: Unit | C21: Low | D21: Base | E21: High | F21: Note / source
A22: Steam wishlists at launch | B22: wishlists | C22: 8000 | D22: 25000 | E22: 60000 | F22: Browser version + Steam Next Fest + cozy creators; see Market sheet
A23: Year-1 units per launch wishlist | B23: x | C23: 0.4 | D23: 0.6 | E23: 0.9 | F23: Rule of thumb: first-year sales ≈ 0.3–1.0× launch wishlists
A24: Year-2 units as % of Year 1 | B24: % | C24: 0.35 | D24: 0.5 | E24: 0.6 | F24: Long tail: seasonal sales, updates, DLC launches
A25: Year-3 units as % of Year 2 | B25: % | C25: 0.5 | D25: 0.6 | E25: 0.7
A26: DLC packs bought per player (avg) | B26: packs | C26: 0.1 | D26: 0.2 | E26: 0.3 | F26: Cosmetic furniture packs; 2 packs released by Year 2
A27: itch.io browser version: tips & supporter pack per year | B27: USD/yr | C27: 1000 | D27: 2500 | E27: 5000 | F27: Browser game stays free (name-your-price) as a funnel

Sheet Development Cost
A1: Development Cost — how the $75,000 budget is spent
A2: Personnel cost = Monthly rate × Months × FTE share. Remote freelance rates (assumption). Producer & Director = the two students (unpaid).
A4: Category | B4: Item | C4: Monthly rate (USD) | D4: Months | E4: FTE share | F4: Cost (USD) | G4: % of budget | H4: Note
A5: Personnel | B5: Lead programmer (building tools, co-op, save system) | C5: 2400 | D5: 9 | E5: 1 | F5: =C5*D5*E5 -> 21600 | G5: =IF($F$26=0,0,F5/$F$26) -> 0.288 | H5: Multi-room homes, resize/recolour, Steam co-op, Workshop
A6: Personnel | B6: Isometric 2D artist (furniture & rooms) | C6: 2000 | D6: 8 | E6: 1 | F6: =C6*D6*E6 -> 16000 | G6: =IF($F$26=0,0,F6/$F$26) -> 0.21333333 | H6: ≈ 400 new pieces + UI art; keeps the original soft pastel style
A7: Personnel | B7: Game designer (content & Cozy Requests) | C7: 1800 | D7: 6 | E7: 1 | F7: =C7*D7*E7 -> 10800 | G7: =IF($F$26=0,0,F7/$F$26) -> 0.144 | H7: Room themes, optional requests, catalogue balance
A8: Personnel | B8: Sound designer / composer | C8: 1500 | D8: 2 | E8: 1 | F8: =C8*D8*E8 -> 3000 | G8: =IF($F$26=0,0,F8/$F$26) -> 0.04 | H8: Satisfying placement sounds + ambient loops (players' favourite feature)
A9: Personnel | B9: QA & playtesting | C9: 800 | D9: 3 | E9: 1 | F9: =C9*D9*E9 -> 2400 | G9: =IF($F$26=0,0,F9/$F$26) -> 0.032 | H9: Last 3 months incl. Steam Next Fest demo
B10: Personnel subtotal | F10: =SUM(F5:F9) -> 53800 | G10: =IF($F$26=0,0,F10/$F$26) -> 0.71733333
A12: Tools & legal | B12: Software & asset licences | F12: 600 | G12: =IF($F$26=0,0,F12/$F$26) -> 0.008 | H12: Engine/tool licences, fonts, SFX libraries
A13: Tools & legal | B13: Steam Direct fee | F13: 100 | G13: =IF($F$26=0,0,F13/$F$26) -> 0.0013333333 | H13: Official one-off fee per game (recoupable)
A14: Tools & legal | B14: Legal & company setup | F14: 800 | G14: =IF($F$26=0,0,F14/$F$26) -> 0.010666667 | H14: Publishing agreement with original developer, EULA
A15: Tools & legal | B15: Localization (EN + 5 languages) | F15: 2500 | G15: =IF($F$26=0,0,F15/$F$26) -> 0.033333333 | H15: ZH, JA, KO, RU, ES — cozy games sell strongly in Asia
A16: Marketing & launch | B16: Cozy creator / streamer campaign | F16: 5000 | G16: =IF($F$26=0,0,F16/$F$26) -> 0.066666667 | H16: Many small cozy & decorating creators (TikTok, YouTube, Twitch)
A17: Marketing & launch | B17: Trailer & Steam page assets | F17: 1500 | G17: =IF($F$26=0,0,F17/$F$26) -> 0.02 | H17: Announcement + launch trailer, capsule art, GIFs
A18: Marketing & launch | B18: Festivals & showcases | F18: 1500 | G18: =IF($F$26=0,0,F18/$F$26) -> 0.02 | H18: Submissions: Wholesome Direct, Cozy Games showcases; Steam Next Fest is free
A19: Marketing & launch | B19: Paid social (TikTok / Reels) | F19: 2000 | G19: =IF($F$26=0,0,F19/$F$26) -> 0.026666667 | H19: 'Room makeover' timelapses
B20: Tools, legal & marketing subtotal | F20: =SUM(F12:F19) -> 14000 | G20: =IF($F$26=0,0,F20/$F$26) -> 0.18666667
B22: Contingency rate | E22: 0.1 | H22: Reserve for delays / scope changes (standard 10%)
A23: Contingency | B23: Contingency reserve | F23: =(F10+F20)*E22 -> 6780 | G23: =IF($F$26=0,0,F23/$F$26) -> 0.0904
B25: TOTAL DEVELOPMENT & LAUNCH COST | F25: =F10+F20+F23 -> 74580 | G25: =IF($F$26=0,0,F25/$F$26) -> 0.9944
B26: Budget (from Assumptions) | F26: =Assumptions!$D$5 -> 75000
B27: Remaining budget (must be ≥ 0) | F27: =F26-F25 -> 420 | G27: =IF(F27>=0,"OK — within budget","OVER BUDGET") -> OK — within budget

Sheet Revenue
A1: Revenue Forecast — Price / Gross Revenue (3 years after Steam launch)
A2: Premium Steam release ($9.99) + cosmetic furniture DLC + soundtrack + free browser version on itch.io (tips).
A4: LOW SCENARIO | B4: Unit | C4: Year 1 | D4: Year 2 | E4: Year 3 | F4: 3-yr total
A5: Steam units sold | B5: copies | C5: =Assumptions!$C$22*Assumptions!$C$23 -> 3200 | D5: =C5*Assumptions!$C$24 -> 1120 | E5: =D5*Assumptions!$C$25 -> 560 | F5: =SUM(C5:E5) -> 4880
A6: Realized price per copy (after discounts & refunds) | B6: USD | C6: =Assumptions!$D$7*(1-Assumptions!$D$8)*(1-Assumptions!$D$9) -> 6.64335 | D6: =Assumptions!$D$7*(1-Assumptions!$D$8)*(1-Assumptions!$D$9) -> 6.64335 | E6: =Assumptions!$D$7*(1-Assumptions!$D$8)*(1-Assumptions!$D$9) -> 6.64335
A7: Game sales, gross | B7: USD | C7: =C5*C6 -> 21258.72 | D7: =D5*D6 -> 7440.552 | E7: =E5*E6 -> 3720.276 | F7: =SUM(C7:E7) -> 32419.548
A8: Furniture DLC packs, gross | B8: USD | C8: =C5*Assumptions!$C$26*Assumptions!$D$12 -> 956.8 | D8: =D5*Assumptions!$C$26*Assumptions!$D$12 -> 334.88 | E8: =E5*Assumptions!$C$26*Assumptions!$D$12 -> 167.44 | F8: =SUM(C8:E8) -> 1459.12
A9: Soundtrack, gross | B9: USD | C9: =C5*Assumptions!$D$14*Assumptions!$D$13 -> 479.04 | D9: =D5*Assumptions!$D$14*Assumptions!$D$13 -> 167.664 | E9: =E5*Assumptions!$D$14*Assumptions!$D$13 -> 83.832 | F9: =SUM(C9:E9) -> 730.536
A10: itch.io browser version (tips, supporter pack) | B10: USD | C10: =Assumptions!$C$27 -> 1000 | D10: =Assumptions!$C$27 -> 1000 | E10: =Assumptions!$C$27 -> 1000 | F10: =SUM(C10:E10) -> 3000
A11: GROSS REVENUE | B11: USD | C11: =SUM(C7:C10) -> 23694.56 | D11: =SUM(D7:D10) -> 8943.096 | E11: =SUM(E7:E10) -> 4971.548 | F11: =SUM(C11:E11) -> 37609.204
A12: – Steam revenue share | B12: USD | C12: =-(C7+C8+C9)*Assumptions!$D$10 -> -6808.368 | D12: =-(D7+D8+D9)*Assumptions!$D$10 -> -2382.9288 | E12: =-(E7+E8+E9)*Assumptions!$D$10 -> -1191.4644 | F12: =SUM(C12:E12) -> -10382.761
A13: – itch.io revenue share | B13: USD | C13: =-C10*Assumptions!$D$11 -> -100 | D13: =-D10*Assumptions!$D$11 -> -100 | E13: =-E10*Assumptions!$D$11 -> -100 | F13: =SUM(C13:E13) -> -300
A14: NET REVENUE (to the team) | B14: USD | C14: =C11+C12+C13 -> 16786.192 | D14: =D11+D12+D13 -> 6460.1672 | E14: =E11+E12+E13 -> 3680.0836 | F14: =SUM(C14:E14) -> 26926.443
A16: BASE SCENARIO | B16: Unit | C16: Year 1 | D16: Year 2 | E16: Year 3 | F16: 3-yr total
A17: Steam units sold | B17: copies | C17: =Assumptions!$D$22*Assumptions!$D$23 -> 15000 | D17: =C17*Assumptions!$D$24 -> 7500 | E17: =D17*Assumptions!$D$25 -> 4500 | F17: =SUM(C17:E17) -> 27000
A18: Realized price per copy (after discounts & refunds) | B18: USD | C18: =Assumptions!$D$7*(1-Assumptions!$D$8)*(1-Assumptions!$D$9) -> 6.64335 | D18: =Assumptions!$D$7*(1-Assumptions!$D$8)*(1-Assumptions!$D$9) -> 6.64335 | E18: =Assumptions!$D$7*(1-Assumptions!$D$8)*(1-Assumptions!$D$9) -> 6.64335
A19: Game sales, gross | B19: USD | C19: =C17*C18 -> 99650.25 | D19: =D17*D18 -> 49825.125 | E19: =E17*E18 -> 29895.075 | F19: =SUM(C19:E19) -> 179370.45
A20: Furniture DLC packs, gross | B20: USD | C20: =C17*Assumptions!$D$26*Assumptions!$D$12 -> 8970 | D20: =D17*Assumptions!$D$26*Assumptions!$D$12 -> 4485 | E20: =E17*Assumptions!$D$26*Assumptions!$D$12 -> 2691 | F20: =SUM(C20:E20) -> 16146
A21: Soundtrack, gross | B21: USD | C21: =C17*Assumptions!$D$14*Assumptions!$D$13 -> 2245.5 | D21: =D17*Assumptions!$D$14*Assumptions!$D$13 -> 1122.75 | E21: =E17*Assumptions!$D$14*Assumptions!$D$13 -> 673.65 | F21: =SUM(C21:E21) -> 4041.9
A22: itch.io browser version (tips, supporter pack) | B22: USD | C22: =Assumptions!$D$27 -> 2500 | D22: =Assumptions!$D$27 -> 2500 | E22: =Assumptions!$D$27 -> 2500 | F22: =SUM(C22:E22) -> 7500
A23: GROSS REVENUE | B23: USD | C23: =SUM(C19:C22) -> 113365.75 | D23: =SUM(D19:D22) -> 57932.875 | E23: =SUM(E19:E22) -> 35759.725 | F23: =SUM(C23:E23) -> 207058.35
A24: – Steam revenue share | B24: USD | C24: =-(C19+C20+C21)*Assumptions!$D$10 -> -33259.725 | D24: =-(D19+D20+D21)*Assumptions!$D$10 -> -16629.862 | E24: =-(E19+E20+E21)*Assumptions!$D$10 -> -9977.9175 | F24: =SUM(C24:E24) -> -59867.505
A25: – itch.io revenue share | B25: USD | C25: =-C22*Assumptions!$D$11 -> -250 | D25: =-D22*Assumptions!$D$11 -> -250 | E25: =-E22*Assumptions!$D$11 -> -250 | F25: =SUM(C25:E25) -> -750
A26: NET REVENUE (to the team) | B26: USD | C26: =C23+C24+C25 -> 79856.025 | D26: =D23+D24+D25 -> 41053.012 | E26: =E23+E24+E25 -> 25531.807 | F26: =SUM(C26:E26) -> 146440.85
A28: HIGH SCENARIO | B28: Unit | C28: Year 1 | D28: Year 2 | E28: Year 3 | F28: 3-yr total
A29: Steam units sold | B29: copies | C29: =Assumptions!$E$22*Assumptions!$E$23 -> 54000 | D29: =C29*Assumptions!$E$24 -> 32400 | E29: =D29*Assumptions!$E$25 -> 22680 | F29: =SUM(C29:E29) -> 109080
A30: Realized price per copy (after discounts & refunds) | B30: USD | C30: =Assumptions!$D$7*(1-Assumptions!$D$8)*(1-Assumptions!$D$9) -> 6.64335 | D30: =Assumptions!$D$7*(1-Assumptions!$D$8)*(1-Assumptions!$D$9) -> 6.64335 | E30: =Assumptions!$D$7*(1-Assumptions!$D$8)*(1-Assumptions!$D$9) -> 6.64335
A31: Game sales, gross | B31: USD | C31: =C29*C30 -> 358740.9 | D31: =D29*D30 -> 215244.54 | E31: =E29*E30 -> 150671.18 | F31: =SUM(C31:E31) -> 724656.62
A32: Furniture DLC packs, gross | B32: USD | C32: =C29*Assumptions!$E$26*Assumptions!$D$12 -> 48438 | D32: =D29*Assumptions!$E$26*Assumptions!$D$12 -> 29062.8 | E32: =E29*Assumptions!$E$26*Assumptions!$D$12 -> 20343.96 | F32: =SUM(C32:E32) -> 97844.76
A33: Soundtrack, gross | B33: USD | C33: =C29*Assumptions!$D$14*Assumptions!$D$13 -> 8083.8 | D33: =D29*Assumptions!$D$14*Assumptions!$D$13 -> 4850.28 | E33: =E29*Assumptions!$D$14*Assumptions!$D$13 -> 3395.196 | F33: =SUM(C33:E33) -> 16329.276
A34: itch.io browser version (tips, supporter pack) | B34: USD | C34: =Assumptions!$E$27 -> 5000 | D34: =Assumptions!$E$27 -> 5000 | E34: =Assumptions!$E$27 -> 5000 | F34: =SUM(C34:E34) -> 15000
A35: GROSS REVENUE | B35: USD | C35: =SUM(C31:C34) -> 420262.7 | D35: =SUM(D31:D34) -> 254157.62 | E35: =SUM(E31:E34) -> 179410.33 | F35: =SUM(C35:E35) -> 853830.65
A36: – Steam revenue share | B36: USD | C36: =-(C31+C32+C33)*Assumptions!$D$10 -> -124578.81 | D36: =-(D31+D32+D33)*Assumptions!$D$10 -> -74747.286 | E36: =-(E31+E32+E33)*Assumptions!$D$10 -> -52323.1 | F36: =SUM(C36:E36) -> -251649.2
A37: – itch.io revenue share | B37: USD | C37: =-C34*Assumptions!$D$11 -> -500 | D37: =-D34*Assumptions!$D$11 -> -500 | E37: =-E34*Assumptions!$D$11 -> -500 | F37: =SUM(C37:E37) -> -1500
A38: NET REVENUE (to the team) | B38: USD | C38: =C35+C36+C37 -> 295183.89 | D38: =D35+D36+D37 -> 178910.33 | E38: =E35+E36+E37 -> 126587.23 | F38: =SUM(C38:E38) -> 600681.46

Sheet P&L & Break-even
A1: Profit & Loss, Cash Flow and Break-even
A2: Year 0 = development (budget spent). Years 1–3 = after Steam launch.
A4: LOW SCENARIO | B4: Year 0 (dev) | C4: Year 1 | D4: Year 2 | E4: Year 3 | F4: Total
A5: Net revenue | B5: 0 | C5: =Revenue!C14 -> 16786.192 | D5: =Revenue!D14 -> 6460.1672 | E5: =Revenue!E14 -> 3680.0836 | F5: =SUM(B5:E5) -> 26926.443
A6: Development & launch cost | B6: =-'Development Cost'!$F$25 -> -74580 | C6: 0 | D6: 0 | E6: 0 | F6: =SUM(B6:E6) -> -74580
A7: Live-ops: monthly furniture drops | B7: 0 | C7: =-Assumptions!$D$15 -> -12000 | D7: =-Assumptions!$D$15 -> -12000 | E7: =-Assumptions!$D$15 -> -12000 | F7: =SUM(B7:E7) -> -36000
A8: Ongoing marketing | B8: 0 | C8: =-Assumptions!$D$16 -> -4000 | D8: =-Assumptions!$D$16 -> -4000 | E8: =-Assumptions!$D$16 -> -4000 | F8: =SUM(B8:E8) -> -12000
A9: Tools, hosting & fees | B9: 0 | C9: =-Assumptions!$D$17 -> -400 | D9: =-Assumptions!$D$17 -> -400 | E9: =-Assumptions!$D$17 -> -400 | F9: =SUM(B9:E9) -> -1200
A10: TOTAL COSTS | B10: =SUM(B6:B9) -> -74580 | C10: =SUM(C6:C9) -> -16400 | D10: =SUM(D6:D9) -> -16400 | E10: =SUM(E6:E9) -> -16400 | F10: =SUM(B10:E10) -> -123780
A11: Profit before tax | B11: =B5+B10 -> -74580 | C11: =C5+C10 -> 386.192 | D11: =D5+D10 -> -9939.8328 | E11: =E5+E10 -> -12719.916 | F11: =SUM(B11:E11) -> -96853.557
A12: Income tax | B12: =-MAX(0,B11)*Assumptions!$D$18 -> 0 | C12: =-MAX(0,C11)*Assumptions!$D$18 -> -38.6192 | D12: =-MAX(0,D11)*Assumptions!$D$18 -> 0 | E12: =-MAX(0,E11)*Assumptions!$D$18 -> 0 | F12: =SUM(B12:E12) -> -38.6192
A13: NET PROFIT / CASH FLOW | B13: =B11+B12 -> -74580 | C13: =C11+C12 -> 347.5728 | D13: =D11+D12 -> -9939.8328 | E13: =E11+E12 -> -12719.916 | F13: =SUM(B13:E13) -> -96892.176
A14: Cumulative cash | B14: =B13 -> -74580 | C14: =B14+C13 -> -74232.427 | D14: =C14+D13 -> -84172.26 | E14: =D14+E13 -> -96892.176
A15: Break-even year | B15: =IF(C14>=0,"Year 1",IF(D14>=0,"Year 2",IF(E14>=0,"Year 3","After Year 3"))) -> After Year 3
A16: ROI after 3 years (cumulative cash ÷ dev cost) | B16: =IF('Development Cost'!$F$25=0,0,E14/'Development Cost'!$F$25) -> -1.299171
A17: NPV of 3 years (at discount rate) | B17: =B13+NPV(Assumptions!$D$19,C13:E13) -> -91247.426
A19: BASE SCENARIO | B19: Year 0 (dev) | C19: Year 1 | D19: Year 2 | E19: Year 3 | F19: Total
A20: Net revenue | B20: 0 | C20: =Revenue!C26 -> 79856.025 | D20: =Revenue!D26 -> 41053.012 | E20: =Revenue!E26 -> 25531.807 | F20: =SUM(B20:E20) -> 146440.85
A21: Development & launch cost | B21: =-'Development Cost'!$F$25 -> -74580 | C21: 0 | D21: 0 | E21: 0 | F21: =SUM(B21:E21) -> -74580
A22: Live-ops: monthly furniture drops | B22: 0 | C22: =-Assumptions!$D$15 -> -12000 | D22: =-Assumptions!$D$15 -> -12000 | E22: =-Assumptions!$D$15 -> -12000 | F22: =SUM(B22:E22) -> -36000
A23: Ongoing marketing | B23: 0 | C23: =-Assumptions!$D$16 -> -4000 | D23: =-Assumptions!$D$16 -> -4000 | E23: =-Assumptions!$D$16 -> -4000 | F23: =SUM(B23:E23) -> -12000
A24: Tools, hosting & fees | B24: 0 | C24: =-Assumptions!$D$17 -> -400 | D24: =-Assumptions!$D$17 -> -400 | E24: =-Assumptions!$D$17 -> -400 | F24: =SUM(B24:E24) -> -1200
A25: TOTAL COSTS | B25: =SUM(B21:B24) -> -74580 | C25: =SUM(C21:C24) -> -16400 | D25: =SUM(D21:D24) -> -16400 | E25: =SUM(E21:E24) -> -16400 | F25: =SUM(B25:E25) -> -123780
A26: Profit before tax | B26: =B20+B25 -> -74580 | C26: =C20+C25 -> 63456.025 | D26: =D20+D25 -> 24653.013 | E26: =E20+E25 -> 9131.8075 | F26: =SUM(B26:E26) -> 22660.845
A27: Income tax | B27: =-MAX(0,B26)*Assumptions!$D$18 -> 0 | C27: =-MAX(0,C26)*Assumptions!$D$18 -> -6345.6025 | D27: =-MAX(0,D26)*Assumptions!$D$18 -> -2465.3012 | E27: =-MAX(0,E26)*Assumptions!$D$18 -> -913.18075 | F27: =SUM(B27:E27) -> -9724.0845
A28: NET PROFIT / CASH FLOW | B28: =B26+B27 -> -74580 | C28: =C26+C27 -> 57110.423 | D28: =D26+D27 -> 22187.711 | E28: =E26+E27 -> 8218.6267 | F28: =SUM(B28:E28) -> 12936.761
A29: Cumulative cash | B29: =B28 -> -74580 | C29: =B29+C28 -> -17469.577 | D29: =C29+D28 -> 4718.1337 | E29: =D29+E28 -> 12936.761
A30: Break-even year | B30: =IF(C29>=0,"Year 1",IF(D29>=0,"Year 2",IF(E29>=0,"Year 3","After Year 3"))) -> Year 2
A31: ROI after 3 years (cumulative cash ÷ dev cost) | B31: =IF('Development Cost'!$F$25=0,0,E29/'Development Cost'!$F$25) -> 0.17346152
A32: NPV of 3 years (at discount rate) | B32: =B28+NPV(Assumptions!$D$19,C28:E28) -> -50.787589
A34: HIGH SCENARIO | B34: Year 0 (dev) | C34: Year 1 | D34: Year 2 | E34: Year 3 | F34: Total
A35: Net revenue | B35: 0 | C35: =Revenue!C38 -> 295183.89 | D35: =Revenue!D38 -> 178910.33 | E35: =Revenue!E38 -> 126587.23 | F35: =SUM(B35:E35) -> 600681.46
A36: Development & launch cost | B36: =-'Development Cost'!$F$25 -> -74580 | C36: 0 | D36: 0 | E36: 0 | F36: =SUM(B36:E36) -> -74580
A37: Live-ops: monthly furniture drops | B37: 0 | C37: =-Assumptions!$D$15 -> -12000 | D37: =-Assumptions!$D$15 -> -12000 | E37: =-Assumptions!$D$15 -> -12000 | F37: =SUM(B37:E37) -> -36000
A38: Ongoing marketing | B38: 0 | C38: =-Assumptions!$D$16 -> -4000 | D38: =-Assumptions!$D$16 -> -4000 | E38: =-Assumptions!$D$16 -> -4000 | F38: =SUM(B38:E38) -> -12000
A39: Tools, hosting & fees | B39: 0 | C39: =-Assumptions!$D$17 -> -400 | D39: =-Assumptions!$D$17 -> -400 | E39: =-Assumptions!$D$17 -> -400 | F39: =SUM(B39:E39) -> -1200
A40: TOTAL COSTS | B40: =SUM(B36:B39) -> -74580 | C40: =SUM(C36:C39) -> -16400 | D40: =SUM(D36:D39) -> -16400 | E40: =SUM(E36:E39) -> -16400 | F40: =SUM(B40:E40) -> -123780
A41: Profit before tax | B41: =B35+B40 -> -74580 | C41: =C35+C40 -> 278783.89 | D41: =D35+D40 -> 162510.33 | E41: =E35+E40 -> 110187.23 | F41: =SUM(B41:E41) -> 476901.46
A42: Income tax | B42: =-MAX(0,B41)*Assumptions!$D$18 -> 0 | C42: =-MAX(0,C41)*Assumptions!$D$18 -> -27878.389 | D42: =-MAX(0,D41)*Assumptions!$D$18 -> -16251.033 | E42: =-MAX(0,E41)*Assumptions!$D$18 -> -11018.723 | F42: =SUM(B42:E42) -> -55148.146
A43: NET PROFIT / CASH FLOW | B43: =B41+B42 -> -74580 | C43: =C41+C42 -> 250905.5 | D43: =D41+D42 -> 146259.3 | E43: =E41+E42 -> 99168.51 | F43: =SUM(B43:E43) -> 421753.31
...

Sheet Market Estimation
A1: Market Estimation — TAM / SAM / SOM
A2: Approximate public figures — verify and add the source link before submitting.
A4: Steam market (players) | B4: Value | C4: Note / source
A5: Steam monthly active users | B5: 130000000 | C5: Valve reported 132M MAU (2021); verify latest figure
A6: Share who buy cozy / sandbox / building games | B6: 0.05 | C6: Assumption — 'Cozy' and 'Building' are large Steam tags
A7: TAM — cozy & sandbox buyers | B7: =B5*B6 -> 6500000 | C7: Formula: MAU × share
A8: Share interested in home / room decorating at < $15 | B8: 0.15 | C8: Assumption
A9: SAM — decorating-game buyers | B9: =B7*B8 -> 975000 | C9: Formula: TAM × share
A10: Share we can win in Year 1 with a $75k budget | B10: 0.0154 | C10: Assumption — calibrated to Base scenario
A11: SOM — Year-1 copies | B11: =B9*B10 -> 15015 | C11: Formula: SAM × share; compare with Revenue → Base units Y1
A12: Base-scenario Steam units in Year 1 (from Revenue) | B12: =Revenue!C17 -> 15000
A14: Demand signals (comparable games) | B14: Value | C14: Note / source
A15: Tiny Glade — copies sold in first month | B15: 616000 | C15: GameDiscoverCo newsletter, Oct 2024 — cozy builder, $15
A16: Townscaper — estimated copies sold | B16: 610000 | C16: Estimate 610k–1.1M, price under $6 — verify on Gamalytic/SteamDB
A17: diorama (Steam version by the original dev) — user reviews | B17: 83 | C17: 95% positive (Very Positive) — proves demand for this exact game
A18: Another Home (itch.io) — player comments | B18: 180 | C18: ≈ 180 comments on the itch.io page, monthly furniture updates

Sheet Roadmap
A1: Roadmap — 10 months development + first year after launch
A2: Change Start month / Duration (blue); the timeline fills automatically.
A4: Phase | B4: Key deliverable / milestone | C4: Start month | D4: Duration (months) | E4: M1 | F4: M2 | G4: M3 | H4: M4 | I4: M5 | J4: M6 | K4: M7 | L4: M8 | M4: M9 | N4: M10 | O4: M11 | P4: M12 | Q4: M13 | R4: M14 | S4: M15 | T4: M16 | U4: M17 | V4: M18
A5: Pre-production | B5: Macro GDD, tech plan, deal with original developer | C5: 1 | D5: 2 | E5: =IF(AND(1>=$C5,1<$C5+$D5),"■","") -> ■ | F5: =IF(AND(2>=$C5,2<$C5+$D5),"■","") -> ■ | G5: =IF(AND(3>=$C5,3<$C5+$D5),"■","") | H5: =IF(AND(4>=$C5,4<$C5+$D5),"■","") | I5: =IF(AND(5>=$C5,5<$C5+$D5),"■","") | J5: =IF(AND(6>=$C5,6<$C5+$D5),"■","") | K5: =IF(AND(7>=$C5,7<$C5+$D5),"■","") | L5: =IF(AND(8>=$C5,8<$C5+$D5),"■","") | M5: =IF(AND(9>=$C5,9<$C5+$D5),"■","") | N5: =IF(AND(10>=$C5,10<$C5+$D5),"■","") | O5: =IF(AND(11>=$C5,11<$C5+$D5),"■","") | P5: =IF(AND(12>=$C5,12<$C5+$D5),"■","") | Q5: =IF(AND(13>=$C5,13<$C5+$D5),"■","") | R5: =IF(AND(14>=$C5,14<$C5+$D5),"■","") | S5: =IF(AND(15>=$C5,15<$C5+$D5),"■","") | T5: =IF(AND(16>=$C5,16<$C5+$D5),"■","") | U5: =IF(AND(17>=$C5,17<$C5+$D5),"■","") | V5: =IF(AND(18>=$C5,18<$C5+$D5),"■","")
A6: Core rebuild | B6: Multi-room homes, resize/recolour, save system | C6: 2 | D6: 3 | E6: =IF(AND(1>=$C6,1<$C6+$D6),"■","") | F6: =IF(AND(2>=$C6,2<$C6+$D6),"■","") -> ■ | G6: =IF(AND(3>=$C6,3<$C6+$D6),"■","") -> ■ | H6: =IF(AND(4>=$C6,4<$C6+$D6),"■","") -> ■ | I6: =IF(AND(5>=$C6,5<$C6+$D6),"■","") | J6: =IF(AND(6>=$C6,6<$C6+$D6),"■","") | K6: =IF(AND(7>=$C6,7<$C6+$D6),"■","") | L6: =IF(AND(8>=$C6,8<$C6+$D6),"■","") | M6: =IF(AND(9>=$C6,9<$C6+$D6),"■","") | N6: =IF(AND(10>=$C6,10<$C6+$D6),"■","") | O6: =IF(AND(11>=$C6,11<$C6+$D6),"■","") | P6: =IF(AND(12>=$C6,12<$C6+$D6),"■","") | Q6: =IF(AND(13>=$C6,13<$C6+$D6),"■","") | R6: =IF(AND(14>=$C6,14<$C6+$D6),"■","") | S6: =IF(AND(15>=$C6,15<$C6+$D6),"■","") | T6: =IF(AND(16>=$C6,16<$C6+$D6),"■","") | U6: =IF(AND(17>=$C6,17<$C6+$D6),"■","") | V6: =IF(AND(18>=$C6,18<$C6+$D6),"■","")
A7: Content production | B7: ≈ 400 new furniture pieces, 6 room themes, sounds | C7: 4 | D7: 5 | E7: =IF(AND(1>=$C7,1<$C7+$D7),"■","") | F7: =IF(AND(2>=$C7,2<$C7+$D7),"■","") | G7: =IF(AND(3>=$C7,3<$C7+$D7),"■","") | H7: =IF(AND(4>=$C7,4<$C7+$D7),"■","") -> ■ | I7: =IF(AND(5>=$C7,5<$C7+$D7),"■","") -> ■ | J7: =IF(AND(6>=$C7,6<$C7+$D7),"■","") -> ■ | K7: =IF(AND(7>=$C7,7<$C7+$D7),"■","") -> ■ | L7: =IF(AND(8>=$C7,8<$C7+$D7),"■","") -> ■ | M7: =IF(AND(9>=$C7,9<$C7+$D7),"■","") | N7: =IF(AND(10>=$C7,10<$C7+$D7),"■","") | O7: =IF(AND(11>=$C7,11<$C7+$D7),"■","") | P7: =IF(AND(12>=$C7,12<$C7+$D7),"■","") | Q7: =IF(AND(13>=$C7,13<$C7+$D7),"■","") | R7: =IF(AND(14>=$C7,14<$C7+$D7),"■","") | S7: =IF(AND(15>=$C7,15<$C7+$D7),"■","") | T7: =IF(AND(16>=$C7,16<$C7+$D7),"■","") | U7: =IF(AND(17>=$C7,17<$C7+$D7),"■","") | V7: =IF(AND(18>=$C7,18<$C7+$D7),"■","")
A8: Steam page live | B8: Wishlist campaign starts (target 5k by M6) | C8: 3 | D8: 1 | E8: =IF(AND(1>=$C8,1<$C8+$D8),"■","") | F8: =IF(AND(2>=$C8,2<$C8+$D8),"■","") | G8: =IF(AND(3>=$C8,3<$C8+$D8),"■","") -> ■ | H8: =IF(AND(4>=$C8,4<$C8+$D8),"■","") | I8: =IF(AND(5>=$C8,5<$C8+$D8),"■","") | J8: =IF(AND(6>=$C8,6<$C8+$D8),"■","") | K8: =IF(AND(7>=$C8,7<$C8+$D8),"■","") | L8: =IF(AND(8>=$C8,8<$C8+$D8),"■","") | M8: =IF(AND(9>=$C8,9<$C8+$D8),"■","") | N8: =IF(AND(10>=$C8,10<$C8+$D8),"■","") | O8: =IF(AND(11>=$C8,11<$C8+$D8),"■","") | P8: =IF(AND(12>=$C8,12<$C8+$D8),"■","") | Q8: =IF(AND(13>=$C8,13<$C8+$D8),"■","") | R8: =IF(AND(14>=$C8,14<$C8+$D8),"■","") | S8: =IF(AND(15>=$C8,15<$C8+$D8),"■","") | T8: =IF(AND(16>=$C8,16<$C8+$D8),"■","") | U8: =IF(AND(17>=$C8,17<$C8+$D8),"■","") | V8: =IF(AND(18>=$C8,18<$C8+$D8),"■","")
A9: Co-op & Cozy Requests | B9: Online co-op decorating, optional requests | C9: 5 | D9: 3 | E9: =IF(AND(1>=$C9,1<$C9+$D9),"■","") | F9: =IF(AND(2>=$C9,2<$C9+$D9),"■","") | G9: =IF(AND(3>=$C9,3<$C9+$D9),"■","") | H9: =IF(AND(4>=$C9,4<$C9+$D9),"■","") | I9: =IF(AND(5>=$C9,5<$C9+$D9),"■","") -> ■ | J9: =IF(AND(6>=$C9,6<$C9+$D9),"■","") -> ■ | K9: =IF(AND(7>=$C9,7<$C9+$D9),"■","") -> ■ | L9: =IF(AND(8>=$C9,8<$C9+$D9),"■","") | M9: =IF(AND(9>=$C9,9<$C9+$D9),"■","") | N9: =IF(AND(10>=$C9,10<$C9+$D9),"■","") | O9: =IF(AND(11>=$C9,11<$C9+$D9),"■","") | P9: =IF(AND(12>=$C9,12<$C9+$D9),"■","") | Q9: =IF(AND(13>=$C9,13<$C9+$D9),"■","") | R9: =IF(AND(14>=$C9,14<$C9+$D9),"■","") | S9: =IF(AND(15>=$C9,15<$C9+$D9),"■","") | T9: =IF(AND(16>=$C9,16<$C9+$D9),"■","") | U9: =IF(AND(17>=$C9,17<$C9+$D9),"■","") | V9: =IF(AND(18>=$C9,18<$C9+$D9),"■","")
A10: Demo + Steam Next Fest | B10: Free demo, creator keys | C10: 8 | D10: 1 | E10: =IF(AND(1>=$C10,1<$C10+$D10),"■","") | F10: =IF(AND(2>=$C10,2<$C10+$D10),"■","") | G10: =IF(AND(3>=$C10,3<$C10+$D10),"■","") | H10: =IF(AND(4>=$C10,4<$C10+$D10),"■","") | I10: =IF(AND(5>=$C10,5<$C10+$D10),"■","") | J10: =IF(AND(6>=$C10,6<$C10+$D10),"■","") | K10: =IF(AND(7>=$C10,7<$C10+$D10),"■","") | L10: =IF(AND(8>=$C10,8<$C10+$D10),"■","") -> ■ | M10: =IF(AND(9>=$C10,9<$C10+$D10),"■","") | N10: =IF(AND(10>=$C10,10<$C10+$D10),"■","") | O10: =IF(AND(11>=$C10,11<$C10+$D10),"■","") | P10: =IF(AND(12>=$C10,12<$C10+$D10),"■","") | Q10: =IF(AND(13>=$C10,13<$C10+$D10),"■","") | R10: =IF(AND(14>=$C10,14<$C10+$D10),"■","") | S10: =IF(AND(15>=$C10,15<$C10+$D10),"■","") | T10: =IF(AND(16>=$C10,16<$C10+$D10),"■","") | U10: =IF(AND(17>=$C10,17<$C10+$D10),"■","") | V10: =IF(AND(18>=$C10,18<$C10+$D10),"■","")
A11: Polish & localization | B11: 5 languages, bug fixing, Steam Deck check | C11: 8 | D11: 2 | E11: =IF(AND(1>=$C11,1<$C11+$D11),"■","") | F11: =IF(AND(2>=$C11,2<$C11+$D11),"■","") | G11: =IF(AND(3>=$C11,3<$C11+$D11),"■","") | H11: =IF(AND(4>=$C11,4<$C11+$D11),"■","") | I11: =IF(AND(5>=$C11,5<$C11+$D11),"■","") | J11: =IF(AND(6>=$C11,6<$C11+$D11),"■","") | K11: =IF(AND(7>=$C11,7<$C11+$D11),"■","") | L11: =IF(AND(8>=$C11,8<$C11+$D11),"■","") -> ■ | M11: =IF(AND(9>=$C11,9<$C11+$D11),"■","") -> ■ | N11: =IF(AND(10>=$C11,10<$C11+$D11),"■","") | O11: =IF(AND(11>=$C11,11<$C11+$D11),"■","") | P11: =IF(AND(12>=$C11,12<$C11+$D11),"■","") | Q11: =IF(AND(13>=$C11,13<$C11+$D11),"■","") | R11: =IF(AND(14>=$C11,14<$C11+$D11),"■","") | S11: =IF(AND(15>=$C11,15<$C11+$D11),"■","") | T11: =IF(AND(16>=$C11,16<$C11+$D11),"■","") | U11: =IF(AND(17>=$C11,17<$C11+$D11),"■","") | V11: =IF(AND(18>=$C11,18<$C11+$D11),"■","")
A12: LAUNCH | B12: Steam release + browser version update on itch.io | C12: 10 | D12: 1 | E12: =IF(AND(1>=$C12,1<$C12+$D12),"■","") | F12: =IF(AND(2>=$C12,2<$C12+$D12),"■","") | G12: =IF(AND(3>=$C12,3<$C12+$D12),"■","") | H12: =IF(AND(4>=$C12,4<$C12+$D12),"■","") | I12: =IF(AND(5>=$C12,5<$C12+$D12),"■","") | J12: =IF(AND(6>=$C12,6<$C12+$D12),"■","") | K12: =IF(AND(7>=$C12,7<$C12+$D12),"■","") | L12: =IF(AND(8>=$C12,8<$C12+$D12),"■","") | M12: =IF(AND(9>=$C12,9<$C12+$D12),"■","") | N12: =IF(AND(10>=$C12,10<$C12+$D12),"■","") -> ■ | O12: =IF(AND(11>=$C12,11<$C12+$D12),"■","") | P12: =IF(AND(12>=$C12,12<$C12+$D12),"■","") | Q12: =IF(AND(13>=$C12,13<$C12+$D12),"■","") | R12: =IF(AND(14>=$C12,14<$C12+$D12),"■","") | S12: =IF(AND(15>=$C12,15<$C12+$D12),"■","") | T12: =IF(AND(16>=$C12,16<$C12+$D12),"■","") | U12: =IF(AND(17>=$C12,17<$C12+$D12),"■","") | V12: =IF(AND(18>=$C12,18<$C12+$D12),"■","")
A13: Monthly furniture drops | B13: Free updates keep the community active | C13: 11 | D13: 8 | E13: =IF(AND(1>=$C13,1<$C13+$D13),"■","") | F13: =IF(AND(2>=$C13,2<$C13+$D13),"■","") | G13: =IF(AND(3>=$C13,3<$C13+$D13),"■","") | H13: =IF(AND(4>=$C13,4<$C13+$D13),"■","") | I13: =IF(AND(5>=$C13,5<$C13+$D13),"■","") | J13: =IF(AND(6>=$C13,6<$C13+$D13),"■","") | K13: =IF(AND(7>=$C13,7<$C13+$D13),"■","") | L13: =IF(AND(8>=$C13,8<$C13+$D13),"■","") | M13: =IF(AND(9>=$C13,9<$C13+$D13),"■","") | N13: =IF(AND(10>=$C13,10<$C13+$D13),"■","") | O13: =IF(AND(11>=$C13,11<$C13+$D13),"■","") -> ■ | P13: =IF(AND(12>=$C13,12<$C13+$D13),"■","") -> ■ | Q13: =IF(AND(13>=$C13,13<$C13+$D13),"■","") -> ■ | R13: =IF(AND(14>=$C13,14<$C13+$D13),"■","") -> ■ | S13: =IF(AND(15>=$C13,15<$C13+$D13),"■","") -> ■ | T13: =IF(AND(16>=$C13,16<$C13+$D13),"■","") -> ■ | U13: =IF(AND(17>=$C13,17<$C13+$D13),"■","") -> ■ | V13: =IF(AND(18>=$C13,18<$C13+$D13),"■","") -> ■
A14: DLC pack #1 / #2 | B14: Cosmetic furniture packs ($2.99) | C14: 13 | D14: 5 | E14: =IF(AND(1>=$C14,1<$C14+$D14),"■","") | F14: =IF(AND(2>=$C14,2<$C14+$D14),"■","") | G14: =IF(AND(3>=$C14,3<$C14+$D14),"■","") | H14: =IF(AND(4>=$C14,4<$C14+$D14),"■","") | I14: =IF(AND(5>=$C14,5<$C14+$D14),"■","") | J14: =IF(AND(6>=$C14,6<$C14+$D14),"■","") | K14: =IF(AND(7>=$C14,7<$C14+$D14),"■","") | L14: =IF(AND(8>=$C14,8<$C14+$D14),"■","") | M14: =IF(AND(9>=$C14,9<$C14+$D14),"■","") | N14: =IF(AND(10>=$C14,10<$C14+$D14),"■","") | O14: =IF(AND(11>=$C14,11<$C14+$D14),"■","") | P14: =IF(AND(12>=$C14,12<$C14+$D14),"■","") | Q14: =IF(AND(13>=$C14,13<$C14+$D14),"■","") -> ■ | R14: =IF(AND(14>=$C14,14<$C14+$D14),"■","") -> ■ | S14: =IF(AND(15>=$C14,15<$C14+$D14),"■","") -> ■ | T14: =IF(AND(16>=$C14,16<$C14+$D14),"■","") -> ■ | U14: =IF(AND(17>=$C14,17<$C14+$D14),"■","") -> ■ | V14: =IF(AND(18>=$C14,18<$C14+$D14),"■","")

Sheet Comparable Games
A1: Comparable cozy decorating / sandbox games
A2: Yellow cells: fill in from each store page before the pitch.
A4: Game | B4: Developer | C4: Link | D4: Platform | E4: Price | F4: Reviews / rating (fill) | G4: What it does | H4: Lesson for Another Home
A5: Another Home (our base game) | B5: lane (emiwa) | C5: https://emiwa.itch.io/home | D5: Browser (itch.io) | E5: Free | G5: Isometric room decorating sandbox, no goals, monthly furniture updates | H5: Proven cozy loop and loyal community — our starting point
A6: diorama | B6: lane (original dev) | C6: https://store.steampowered.com/app/2887460/diorama/ | D6: Steam (PC) | E6: Check page | G6: Steam version: ≈ 1000 pieces, resize, weather & time, online & LAN co-op; 95% of 83 reviews positive | H6: Validates demand; our plan must add clear value on top
A7: Tiny Glade | B7: Pounce Light | C7: https://store.steampowered.com/app/2198150/Tiny_Glade/ | D7: Steam (PC) | E7: $15 | G7: Goal-less diorama castle builder; 616k copies in first month | H7: 'No goals' sandbox can sell huge with a strong visual hook
A8: Townscaper | B8: Oskar Stålberg | C8: https://store.steampowered.com/app/1291340/Townscaper/ | D8: PC, Switch, mobile | E8: ≈ $6 | G8: Toy-like town builder, no goals | H8: Cheap price + shareable screenshots = long tail
A9: Unpacking | B9: Witch Beam | C9: https://store.steampowered.com/app/1135690/Unpacking/ | D9: PC, consoles | E9: ≈ $20 | G9: Zen puzzle of unpacking belongings into rooms | H9: Room + object story works; light goals help retention

Sheet How to use
A1: How to use this model
A2: 1. Change inputs only on 'Assumptions' and 'Development Cost' (blue text). Everything else recalculates.
A3: 2. Yellow cells are key assumptions — be ready to explain them in the pitch.
A4: 3. 'Summary' holds the numbers for the Pitchdeck: Price / Gross Revenue, Market Estimation, Targets, Development Cost.
A5: 4. 'Market Estimation' and 'Comparable Games' use approximate public figures — verify and add sources.
A7: Colour code: blue = input · black = formula · green = link to another sheet · yellow fill = key assumption
A8: Example input: Assumptions → 'Steam wishlists at launch' Low 8,000 / Base 25,000 / High 60,000.
