Workbook

Sheet Summary
A1: MoneyWise — Financial Model Summary (for Pitchdeck)
A2: Team 7 · Intro to Game Planning 2026-2 · Budget from course sheet · All values USD · Everything here is calculated — edit the Assumptions sheet
A4: Pricing (Price slide) | B4: Value
A5: Core game (web + mobile) | B5: Free
A6: Premium scenario pack (IAP) | B6: =Assumptions!$D$7 -> 2.99
A7: B2B classroom / institution license (Base, per year) | B7: =Assumptions!$D$29 -> 2000
A8: Production budget | B8: =Assumptions!$D$5 -> 75000
A9: Planned development + launch cost | B9: ='Development Cost'!$F$26 -> 74496.4
A11: Scenario comparison (Gross Revenue & Targets slides) | B11: Low | C11: Base | D11: High | E11: Unit
A12: Players — Year 1 | B12: =Revenue!C5 -> 40000 | C12: =Revenue!C19 -> 120000 | D12: =Revenue!C33 -> 300000 | E12: players
A13: Paying players — Year 1 | B13: =Revenue!C8 -> 600 | C13: =Revenue!C22 -> 3600 | D13: =Revenue!C36 -> 15000 | E13: players
A14: B2B licenses — Year 1 | B14: =Revenue!C11 -> 3 | C14: =Revenue!C25 -> 8 | D14: =Revenue!C39 -> 15 | E14: licenses
A15: Gross revenue — Year 1 | B15: =Revenue!C13 -> 7491 | C15: =Revenue!C27 -> 39028 | D15: =Revenue!C41 -> 163125 | E15: USD
A16: Gross revenue — Year 2 | B16: =Revenue!D13 -> 10790.1 | C16: =Revenue!D27 -> 64239.2 | D16: =Revenue!D41 -> 314812.5 | E16: USD
A17: Gross revenue — Year 3 | B17: =Revenue!E13 -> 13790.1 | C17: =Revenue!E27 -> 90687.04 | D17: =Revenue!E41 -> 509137.5 | E17: USD
A18: Gross revenue — 3 years total | B18: =Revenue!F13 -> 32071.2 | C18: =Revenue!F27 -> 193954.24 | D18: =Revenue!F41 -> 987075 | E18: USD
A19: Net revenue — 3 years total | B19: =Revenue!F16 -> 28744.8 | C19: =Revenue!F30 -> 172974.96 | D19: =Revenue!F44 -> 877175.62 | E19: USD
A20: Net profit incl. development — 3 years | B20: ='P&L & Break-even'!F14 -> -103801.6 | C20: ='P&L & Break-even'!F30 -> 24211.064 | D20: ='P&L & Break-even'!F46 -> 647326.66 | E20: USD
A21: ROI after 3 years | B21: ='P&L & Break-even'!B17 -> -1.3933774 | C21: ='P&L & Break-even'!B33 -> 0.32499643 | D21: ='P&L & Break-even'!B49 -> 8.6893684 | E21: %
A22: NPV of 3 years | B22: ='P&L & Break-even'!B18 -> -98417.521 | C22: ='P&L & Break-even'!B34 -> 984.1897 | D22: ='P&L & Break-even'!B50 -> 479076.37 | E22: USD
A23: Break-even | B23: ='P&L & Break-even'!B16 -> After Year 3 | C23: ='P&L & Break-even'!B32 -> Year 3 | D23: ='P&L & Break-even'!B48 -> Year 1
A25: Revenue mix — Base, 3 years (Gross Revenue slide) | B25: USD | C25: % of gross
A26: Scenario packs (IAP) | B26: =Revenue!F23 -> 87834.24 | C26: =IF($B$29=0,0,B26/$B$29) -> 0.45286063
A27: Rewarded web ads | B27: =Revenue!F24 -> 6120 | C27: =IF($B$29=0,0,B27/$B$29) -> 0.031553835
A28: B2B licenses | B28: =Revenue!F26 -> 100000 | C28: =IF($B$29=0,0,B28/$B$29) -> 0.51558553
A29: Total gross | B29: =SUM(B26:B28) -> 193954.24 | C29: =IF($B$29=0,0,B29/$B$29) -> 1
A31: Budget split (Development Cost slide) | B31: USD | C31: % of budget
A32: Team (personnel) | B32: ='Development Cost'!F11 -> 50500 | C32: ='Development Cost'!G11 -> 0.67333333
A33: Tools, legal & marketing | B33: ='Development Cost'!F21 -> 17224 | C33: ='Development Cost'!G21 -> 0.22965333
A34: Contingency | B34: ='Development Cost'!F24 -> 6772.4 | C34: ='Development Cost'!G24 -> 0.090298667

Sheet Assumptions
A1: MoneyWise — Key Assumptions (edit blue cells only)
A2: Blue = input you can change · Yellow = key assumption to defend in the pitch · All money in USD
A4: General parameter | B4: Unit | D4: Value | F4: Note / source
A5: Production budget | B5: USD | D5: 75000 | F5: From course sheet 'List of Groups', Team 7 budget
A6: Development duration | B6: months | D6: 9 | F6: Pre-production → launch, see Roadmap
A7: Scenario pack price (IAP) | B7: USD | D7: 2.99 | F7: Assumption: typical low-tier mobile IAP price point
A8: itch.io revenue share | B8: % | D8: 0.1 | F8: itch.io default revenue share is 10% (adjustable by dev)
A9: App Store / Google Play fee | B9: % | D9: 0.15 | F9: Small-business programs of Apple & Google: 15% under $1M/yr
A10: Share of players on mobile | B10: % | D10: 0.5 | F10: Assumption: rest play the web build (itch.io / portals)
A11: B2B sales / reseller fee | B11: % | D11: 0.1 | F11: Assumption: commission to edu-reseller or sales partner
A12: Live-ops & new content per year | B12: USD/yr | D12: 12000 | F12: Assumption: part-time designer+dev for new scenario packs
A13: Ongoing marketing per year | B13: USD/yr | D13: 6000 | F13: Assumption: creators + small paid social after launch
A14: Hosting, tools & store accounts per year | B14: USD/yr | D14: 600 | F14: Web hosting, Godot is free; Apple $99/yr, Google $25 one-off
A15: Support cost per B2B license | B15: USD/license | D15: 150 | F15: Assumption: onboarding + teacher support
A16: Income tax rate | B16: % | D16: 0.1 | F16: Simplified assumption — check local SME rate
A17: Discount rate (NPV) | B17: % | D17: 0.12 | F17: Assumption: typical for small risky indie project
A19: Scenario parameter | B19: Unit | C19: Low | D19: Base | E19: High | F19: Note / source
A20: Players in Year 1 (web plays + installs) | B20: players | C20: 40000 | D20: 120000 | E20: 300000 | F20: Benchmark: popular itch.io browser games reach 10k–1M+ plays; see Market sheet (SOM)
A21: Player growth Year 2 | B21: % | C21: 0.1 | D21: 0.4 | E21: 0.7 | F21: Driven by new scenario packs + creator content
A22: Player growth Year 3 | B22: % | C22: 0 | D22: 0.2 | E22: 0.4
A23: Paying conversion (buy ≥1 pack) | B23: % | C23: 0.015 | D23: 0.03 | E23: 0.05 | F23: Freemium mobile/edu games usually convert 1–5% of players
A24: Packs bought per paying player | B24: packs | C24: 1.5 | D24: 2 | E24: 2.5 | F24: 4 packs planned: first job, credit card, investing, first home
A25: Ad revenue per 1,000 web players | B25: USD | C25: 15 | D25: 25 | E25: 40 | F25: Web portal (CrazyGames/Poki-style) revenue share, rewarded ads only
A26: B2B licenses in Year 1 (schools, credit unions, employers) | B26: licenses | C26: 3 | D26: 8 | E26: 15 | F26: Pilot schools from teacher outreach
A27: B2B license growth Year 2 | B27: % | C27: 0.5 | D27: 1 | E27: 1.5
A28: B2B license growth Year 3 | B28: % | C28: 0.3 | D28: 0.6 | E28: 1
A29: Average B2B license price per year | B29: USD/yr | C29: 1500 | D29: 2000 | E29: 3000 | F29: Classroom site license; credit unions/employers pay more

Sheet Development Cost
A1: Development Cost — how the $75,000 budget is spent
A2: Personnel cost = Monthly rate × Months × FTE share. Remote freelance rates (assumption).
A4: Category | B4: Item | C4: Monthly rate (USD) | D4: Months | E4: FTE share | F4: Cost (USD) | G4: % of budget | H4: Note
A5: Personnel | B5: Game designer / scenario writer (lead) | C5: 2000 | D5: 9 | E5: 1 | F5: =C5*D5*E5 -> 18000 | G5: =IF($F$27=0,0,F5/$F$27) -> 0.24 | H5: Writes branching financial scenarios, tunes economy model
A6: Personnel | B6: Godot programmer (web + mobile export) | C6: 2200 | D6: 8 | E6: 1 | F6: =C6*D6*E6 -> 17600 | G6: =IF($F$27=0,0,F6/$F$27) -> 0.23466667 | H6: Single Godot 4 build → HTML5, iOS, Android
A7: Personnel | B7: 2D artist / UI designer | C7: 1800 | D7: 5 | E7: 1 | F7: =C7*D7*E7 -> 9000 | G7: =IF($F$27=0,0,F7/$F$27) -> 0.12 | H7: Flat illustrations, UI, 'consequence' animations
A8: Personnel | B8: Finance expert (consultant) | C8: 1000 | D8: 4 | E8: 0.5 | F8: =C8*D8*E8 -> 2000 | G8: =IF($F$27=0,0,F8/$F$27) -> 0.026666667 | H8: Checks scenarios are realistic — key for B2B credibility
A9: Personnel | B9: QA & playtesting | C9: 800 | D9: 3 | E9: 1 | F9: =C9*D9*E9 -> 2400 | G9: =IF($F$27=0,0,F9/$F$27) -> 0.032 | H9: Last 3 months + school pilot testing
A10: Personnel | B10: Sound & music (freelance) | C10: 1500 | D10: 1 | E10: 1 | F10: =C10*D10*E10 -> 1500 | G10: =IF($F$27=0,0,F10/$F$27) -> 0.02 | H10: Lump sum: SFX pack + 2–3 music tracks
B11: Personnel subtotal | F11: =SUM(F5:F10) -> 50500 | G11: =IF($F$27=0,0,F11/$F$27) -> 0.67333333
A13: Tools & legal | B13: Software, asset licenses, cloud | F13: 600 | G13: =IF($F$27=0,0,F13/$F$27) -> 0.008 | H13: Godot is free; fonts, SFX libraries, cloud storage
A14: Tools & legal | B14: Store accounts (Apple $99 + Google $25) | F14: 124 | G14: =IF($F$27=0,0,F14/$F$27) -> 0.0016533333 | H14: Official developer program fees
A15: Tools & legal | B15: Legal: company, privacy policy, minors' data | F15: 1500 | G15: =IF($F$27=0,0,F15/$F$27) -> 0.02 | H15: Needed for schools (COPPA/GDPR-style rules)
A16: Tools & legal | B16: Localization (2 languages) | F16: 1500 | G16: =IF($F$27=0,0,F16/$F$27) -> 0.02 | H16: e.g. Spanish + Korean/Russian
A17: Marketing & launch | B17: Creator / influencer campaign | F17: 6000 | G17: =IF($F$27=0,0,F17/$F$27) -> 0.08 | H17: Many small personal-finance & indie creators
A18: Marketing & launch | B18: Paid social (TikTok / Reels / Shorts) | F18: 3000 | G18: =IF($F$27=0,0,F18/$F$27) -> 0.04 | H18: 'One choice, two futures' clips
A19: Marketing & launch | B19: Trailer & store assets | F19: 1500 | G19: =IF($F$27=0,0,F19/$F$27) -> 0.02 | H19: Trailer, screenshots, Steam-style page
A20: Marketing & launch | B20: B2B pilot materials & 1 edu conference | F20: 3000 | G20: =IF($F$27=0,0,F20/$F$27) -> 0.04 | H20: Teacher guide, lesson plans, booth/travel
B21: Tools, legal & marketing subtotal | F21: =SUM(F13:F20) -> 17224 | G21: =IF($F$27=0,0,F21/$F$27) -> 0.22965333
B23: Contingency rate | E23: 0.1 | H23: Reserve for delays / scope changes (standard 10%)
A24: Contingency | B24: Contingency reserve | F24: =(F11+F21)*E23 -> 6772.4 | G24: =IF($F$27=0,0,F24/$F$27) -> 0.090298667
B26: TOTAL DEVELOPMENT & LAUNCH COST | F26: =F11+F21+F24 -> 74496.4 | G26: =IF($F$27=0,0,F26/$F$27) -> 0.99328533
B27: Budget (from Assumptions) | F27: =Assumptions!$D$5 -> 75000
B28: Remaining budget (must be ≥ 0) | F28: =F27-F26 -> 503.6 | G28: =IF(F28>=0,"OK — within budget","OVER BUDGET") -> OK — within budget

Sheet Revenue
A1: Revenue Forecast — Price / Gross Revenue (3 years after launch)
A2: Free core game + premium scenario packs (IAP) + rewarded web ads + B2B licenses. All three scenarios shown.
A4: LOW SCENARIO | B4: Unit | C4: Year 1 | D4: Year 2 | E4: Year 3 | F4: 3-yr total
A5: Players | B5: players | C5: =Assumptions!$C$20 -> 40000 | D5: =C5*(1+Assumptions!$C$21) -> 44000 | E5: =D5*(1+Assumptions!$C$22) -> 44000 | F5: =SUM(C5:E5) -> 128000
A6: of which mobile | B6: players | C6: =C5*Assumptions!$D$10 -> 20000 | D6: =D5*Assumptions!$D$10 -> 22000 | E6: =E5*Assumptions!$D$10 -> 22000 | F6: =SUM(C6:E6) -> 64000
A7: of which web | B7: players | C7: =C5-C6 -> 20000 | D7: =D5-D6 -> 22000 | E7: =E5-E6 -> 22000 | F7: =SUM(C7:E7) -> 64000
A8: Paying players | B8: players | C8: =C5*Assumptions!$C$23 -> 600 | D8: =D5*Assumptions!$C$23 -> 660 | E8: =E5*Assumptions!$C$23 -> 660 | F8: =SUM(C8:E8) -> 1920
A9: Scenario pack sales (IAP), gross | B9: USD | C9: =C8*Assumptions!$C$24*Assumptions!$D$7 -> 2691 | D9: =D8*Assumptions!$C$24*Assumptions!$D$7 -> 2960.1 | E9: =E8*Assumptions!$C$24*Assumptions!$D$7 -> 2960.1 | F9: =SUM(C9:E9) -> 8611.2
A10: Rewarded ads on web portals | B10: USD | C10: =C7/1000*Assumptions!$C$25 -> 300 | D10: =D7/1000*Assumptions!$C$25 -> 330 | E10: =E7/1000*Assumptions!$C$25 -> 330 | F10: =SUM(C10:E10) -> 960
A11: B2B licenses (active) | B11: licenses | C11: =Assumptions!$C$26 -> 3 | D11: =ROUND(C11*(1+Assumptions!$C$27),0) -> 5 | E11: =ROUND(D11*(1+Assumptions!$C$28),0) -> 7
A12: B2B licensing revenue, gross | B12: USD | C12: =C11*Assumptions!$C$29 -> 4500 | D12: =D11*Assumptions!$C$29 -> 7500 | E12: =E11*Assumptions!$C$29 -> 10500 | F12: =SUM(C12:E12) -> 22500
A13: GROSS REVENUE | B13: USD | C13: =C9+C10+C12 -> 7491 | D13: =D9+D10+D12 -> 10790.1 | E13: =E9+E10+E12 -> 13790.1 | F13: =SUM(C13:E13) -> 32071.2
A14: – Platform fees on IAP (stores / itch.io) | B14: USD | C14: =-C9*(Assumptions!$D$10*Assumptions!$D$9+(1-Assumptions!$D$10)*Assumptions!$D$8) -> -336.375 | D14: =-D9*(Assumptions!$D$10*Assumptions!$D$9+(1-Assumptions!$D$10)*Assumptions!$D$8) -> -370.0125 | E14: =-E9*(Assumptions!$D$10*Assumptions!$D$9+(1-Assumptions!$D$10)*Assumptions!$D$8) -> -370.0125 | F14: =SUM(C14:E14) -> -1076.4
A15: – B2B sales fee | B15: USD | C15: =-C12*Assumptions!$D$11 -> -450 | D15: =-D12*Assumptions!$D$11 -> -750 | E15: =-E12*Assumptions!$D$11 -> -1050 | F15: =SUM(C15:E15) -> -2250
A16: NET REVENUE | B16: USD | C16: =C13+C14+C15 -> 6704.625 | D16: =D13+D14+D15 -> 9670.0875 | E16: =E13+E14+E15 -> 12370.087 | F16: =SUM(C16:E16) -> 28744.8
A18: BASE SCENARIO | B18: Unit | C18: Year 1 | D18: Year 2 | E18: Year 3 | F18: 3-yr total
A19: Players | B19: players | C19: =Assumptions!$D$20 -> 120000 | D19: =C19*(1+Assumptions!$D$21) -> 168000 | E19: =D19*(1+Assumptions!$D$22) -> 201600 | F19: =SUM(C19:E19) -> 489600
A20: of which mobile | B20: players | C20: =C19*Assumptions!$D$10 -> 60000 | D20: =D19*Assumptions!$D$10 -> 84000 | E20: =E19*Assumptions!$D$10 -> 100800 | F20: =SUM(C20:E20) -> 244800
A21: of which web | B21: players | C21: =C19-C20 -> 60000 | D21: =D19-D20 -> 84000 | E21: =E19-E20 -> 100800 | F21: =SUM(C21:E21) -> 244800
A22: Paying players | B22: players | C22: =C19*Assumptions!$D$23 -> 3600 | D22: =D19*Assumptions!$D$23 -> 5040 | E22: =E19*Assumptions!$D$23 -> 6048 | F22: =SUM(C22:E22) -> 14688
A23: Scenario pack sales (IAP), gross | B23: USD | C23: =C22*Assumptions!$D$24*Assumptions!$D$7 -> 21528 | D23: =D22*Assumptions!$D$24*Assumptions!$D$7 -> 30139.2 | E23: =E22*Assumptions!$D$24*Assumptions!$D$7 -> 36167.04 | F23: =SUM(C23:E23) -> 87834.24
A24: Rewarded ads on web portals | B24: USD | C24: =C21/1000*Assumptions!$D$25 -> 1500 | D24: =D21/1000*Assumptions!$D$25 -> 2100 | E24: =E21/1000*Assumptions!$D$25 -> 2520 | F24: =SUM(C24:E24) -> 6120
A25: B2B licenses (active) | B25: licenses | C25: =Assumptions!$D$26 -> 8 | D25: =ROUND(C25*(1+Assumptions!$D$27),0) -> 16 | E25: =ROUND(D25*(1+Assumptions!$D$28),0) -> 26
A26: B2B licensing revenue, gross | B26: USD | C26: =C25*Assumptions!$D$29 -> 16000 | D26: =D25*Assumptions!$D$29 -> 32000 | E26: =E25*Assumptions!$D$29 -> 52000 | F26: =SUM(C26:E26) -> 100000
A27: GROSS REVENUE | B27: USD | C27: =C23+C24+C26 -> 39028 | D27: =D23+D24+D26 -> 64239.2 | E27: =E23+E24+E26 -> 90687.04 | F27: =SUM(C27:E27) -> 193954.24
A28: – Platform fees on IAP (stores / itch.io) | B28: USD | C28: =-C23*(Assumptions!$D$10*Assumptions!$D$9+(1-Assumptions!$D$10)*Assumptions!$D$8) -> -2691 | D28: =-D23*(Assumptions!$D$10*Assumptions!$D$9+(1-Assumptions!$D$10)*Assumptions!$D$8) -> -3767.4 | E28: =-E23*(Assumptions!$D$10*Assumptions!$D$9+(1-Assumptions!$D$10)*Assumptions!$D$8) -> -4520.88 | F28: =SUM(C28:E28) -> -10979.28
A29: – B2B sales fee | B29: USD | C29: =-C26*Assumptions!$D$11 -> -1600 | D29: =-D26*Assumptions!$D$11 -> -3200 | E29: =-E26*Assumptions!$D$11 -> -5200 | F29: =SUM(C29:E29) -> -10000
A30: NET REVENUE | B30: USD | C30: =C27+C28+C29 -> 34737 | D30: =D27+D28+D29 -> 57271.8 | E30: =E27+E28+E29 -> 80966.16 | F30: =SUM(C30:E30) -> 172974.96
A32: HIGH SCENARIO | B32: Unit | C32: Year 1 | D32: Year 2 | E32: Year 3 | F32: 3-yr total
A33: Players | B33: players | C33: =Assumptions!$E$20 -> 300000 | D33: =C33*(1+Assumptions!$E$21) -> 510000 | E33: =D33*(1+Assumptions!$E$22) -> 714000 | F33: =SUM(C33:E33) -> 1524000
A34: of which mobile | B34: players | C34: =C33*Assumptions!$D$10 -> 150000 | D34: =D33*Assumptions!$D$10 -> 255000 | E34: =E33*Assumptions!$D$10 -> 357000 | F34: =SUM(C34:E34) -> 762000
A35: of which web | B35: players | C35: =C33-C34 -> 150000 | D35: =D33-D34 -> 255000 | E35: =E33-E34 -> 357000 | F35: =SUM(C35:E35) -> 762000
A36: Paying players | B36: players | C36: =C33*Assumptions!$E$23 -> 15000 | D36: =D33*Assumptions!$E$23 -> 25500 | E36: =E33*Assumptions!$E$23 -> 35700 | F36: =SUM(C36:E36) -> 76200
A37: Scenario pack sales (IAP), gross | B37: USD | C37: =C36*Assumptions!$E$24*Assumptions!$D$7 -> 112125 | D37: =D36*Assumptions!$E$24*Assumptions!$D$7 -> 190612.5 | E37: =E36*Assumptions!$E$24*Assumptions!$D$7 -> 266857.5 | F37: =SUM(C37:E37) -> 569595
A38: Rewarded ads on web portals | B38: USD | C38: =C35/1000*Assumptions!$E$25 -> 6000 | D38: =D35/1000*Assumptions!$E$25 -> 10200 | E38: =E35/1000*Assumptions!$E$25 -> 14280 | F38: =SUM(C38:E38) -> 30480
A39: B2B licenses (active) | B39: licenses | C39: =Assumptions!$E$26 -> 15 | D39: =ROUND(C39*(1+Assumptions!$E$27),0) -> 38 | E39: =ROUND(D39*(1+Assumptions!$E$28),0) -> 76
A40: B2B licensing revenue, gross | B40: USD | C40: =C39*Assumptions!$E$29 -> 45000 | D40: =D39*Assumptions!$E$29 -> 114000 | E40: =E39*Assumptions!$E$29 -> 228000 | F40: =SUM(C40:E40) -> 387000
A41: GROSS REVENUE | B41: USD | C41: =C37+C38+C40 -> 163125 | D41: =D37+D38+D40 -> 314812.5 | E41: =E37+E38+E40 -> 509137.5 | F41: =SUM(C41:E41) -> 987075
A42: – Platform fees on IAP (stores / itch.io) | B42: USD | C42: =-C37*(Assumptions!$D$10*Assumptions!$D$9+(1-Assumptions!$D$10)*Assumptions!$D$8) -> -14015.625 | D42: =-D37*(Assumptions!$D$10*Assumptions!$D$9+(1-Assumptions!$D$10)*Assumptions!$D$8) -> -23826.562 | E42: =-E37*(Assumptions!$D$10*Assumptions!$D$9+(1-Assumptions!$D$10)*Assumptions!$D$8) -> -33357.188 | F42: =SUM(C42:E42) -> -71199.375
A43: – B2B sales fee | B43: USD | C43: =-C40*Assumptions!$D$11 -> -4500 | D43: =-D40*Assumptions!$D$11 -> -11400 | E43: =-E40*Assumptions!$D$11 -> -22800 | F43: =SUM(C43:E43) -> -38700
...

Sheet P&L & Break-even
A1: Profit & Loss, Cash Flow and Break-even
A2: Year 0 = development (budget spent). Years 1–3 = after launch.
A4: LOW SCENARIO | B4: Year 0 (dev) | C4: Year 1 | D4: Year 2 | E4: Year 3 | F4: Total
A5: Net revenue | B5: 0 | C5: =Revenue!C16 -> 6704.625 | D5: =Revenue!D16 -> 9670.0875 | E5: =Revenue!E16 -> 12370.087 | F5: =SUM(B5:E5) -> 28744.8
A6: Development & launch cost | B6: =-'Development Cost'!$F$26 -> -74496.4 | C6: 0 | D6: 0 | E6: 0 | F6: =SUM(B6:E6) -> -74496.4
A7: Live-ops & new scenario packs | B7: 0 | C7: =-Assumptions!$D$12 -> -12000 | D7: =-Assumptions!$D$12 -> -12000 | E7: =-Assumptions!$D$12 -> -12000 | F7: =SUM(B7:E7) -> -36000
A8: Ongoing marketing | B8: 0 | C8: =-Assumptions!$D$13 -> -6000 | D8: =-Assumptions!$D$13 -> -6000 | E8: =-Assumptions!$D$13 -> -6000 | F8: =SUM(B8:E8) -> -18000
A9: Hosting, tools, store accounts | B9: 0 | C9: =-Assumptions!$D$14 -> -600 | D9: =-Assumptions!$D$14 -> -600 | E9: =-Assumptions!$D$14 -> -600 | F9: =SUM(B9:E9) -> -1800
A10: B2B customer support | B10: 0 | C10: =-Revenue!C11*Assumptions!$D$15 -> -450 | D10: =-Revenue!D11*Assumptions!$D$15 -> -750 | E10: =-Revenue!E11*Assumptions!$D$15 -> -1050 | F10: =SUM(B10:E10) -> -2250
A11: TOTAL COSTS | B11: =SUM(B6:B10) -> -74496.4 | C11: =SUM(C6:C10) -> -19050 | D11: =SUM(D6:D10) -> -19350 | E11: =SUM(E6:E10) -> -19650 | F11: =SUM(B11:E11) -> -132546.4
A12: Profit before tax | B12: =B5+B11 -> -74496.4 | C12: =C5+C11 -> -12345.375 | D12: =D5+D11 -> -9679.9125 | E12: =E5+E11 -> -7279.9125 | F12: =SUM(B12:E12) -> -103801.6
A13: Income tax | B13: =-MAX(0,B12)*Assumptions!$D$16 -> 0 | C13: =-MAX(0,C12)*Assumptions!$D$16 -> 0 | D13: =-MAX(0,D12)*Assumptions!$D$16 -> 0 | E13: =-MAX(0,E12)*Assumptions!$D$16 -> 0 | F13: =SUM(B13:E13) -> 0
A14: NET PROFIT / CASH FLOW | B14: =B12+B13 -> -74496.4 | C14: =C12+C13 -> -12345.375 | D14: =D12+D13 -> -9679.9125 | E14: =E12+E13 -> -7279.9125 | F14: =SUM(B14:E14) -> -103801.6
A15: Cumulative cash | B15: =B14 -> -74496.4 | C15: =B15+C14 -> -86841.775 | D15: =C15+D14 -> -96521.688 | E15: =D15+E14 -> -103801.6
A16: Break-even year | B16: =IF(C15>=0,"Year 1",IF(D15>=0,"Year 2",IF(E15>=0,"Year 3","After Year 3"))) -> After Year 3
A17: ROI after 3 years (cumulative cash ÷ budget) | B17: =IF('Development Cost'!$F$26=0,0,E15/'Development Cost'!$F$26) -> -1.3933774
A18: NPV of 3 years (at discount rate) | B18: =B14+NPV(Assumptions!$D$17,C14:E14) -> -98417.521
A20: BASE SCENARIO | B20: Year 0 (dev) | C20: Year 1 | D20: Year 2 | E20: Year 3 | F20: Total
A21: Net revenue | B21: 0 | C21: =Revenue!C30 -> 34737 | D21: =Revenue!D30 -> 57271.8 | E21: =Revenue!E30 -> 80966.16 | F21: =SUM(B21:E21) -> 172974.96
A22: Development & launch cost | B22: =-'Development Cost'!$F$26 -> -74496.4 | C22: 0 | D22: 0 | E22: 0 | F22: =SUM(B22:E22) -> -74496.4
A23: Live-ops & new scenario packs | B23: 0 | C23: =-Assumptions!$D$12 -> -12000 | D23: =-Assumptions!$D$12 -> -12000 | E23: =-Assumptions!$D$12 -> -12000 | F23: =SUM(B23:E23) -> -36000
A24: Ongoing marketing | B24: 0 | C24: =-Assumptions!$D$13 -> -6000 | D24: =-Assumptions!$D$13 -> -6000 | E24: =-Assumptions!$D$13 -> -6000 | F24: =SUM(B24:E24) -> -18000
A25: Hosting, tools, store accounts | B25: 0 | C25: =-Assumptions!$D$14 -> -600 | D25: =-Assumptions!$D$14 -> -600 | E25: =-Assumptions!$D$14 -> -600 | F25: =SUM(B25:E25) -> -1800
A26: B2B customer support | B26: 0 | C26: =-Revenue!C25*Assumptions!$D$15 -> -1200 | D26: =-Revenue!D25*Assumptions!$D$15 -> -2400 | E26: =-Revenue!E25*Assumptions!$D$15 -> -3900 | F26: =SUM(B26:E26) -> -7500
A27: TOTAL COSTS | B27: =SUM(B22:B26) -> -74496.4 | C27: =SUM(C22:C26) -> -19800 | D27: =SUM(D22:D26) -> -21000 | E27: =SUM(E22:E26) -> -22500 | F27: =SUM(B27:E27) -> -137796.4
A28: Profit before tax | B28: =B21+B27 -> -74496.4 | C28: =C21+C27 -> 14937 | D28: =D21+D27 -> 36271.8 | E28: =E21+E27 -> 58466.16 | F28: =SUM(B28:E28) -> 35178.56
A29: Income tax | B29: =-MAX(0,B28)*Assumptions!$D$16 -> 0 | C29: =-MAX(0,C28)*Assumptions!$D$16 -> -1493.7 | D29: =-MAX(0,D28)*Assumptions!$D$16 -> -3627.18 | E29: =-MAX(0,E28)*Assumptions!$D$16 -> -5846.616 | F29: =SUM(B29:E29) -> -10967.496
A30: NET PROFIT / CASH FLOW | B30: =B28+B29 -> -74496.4 | C30: =C28+C29 -> 13443.3 | D30: =D28+D29 -> 32644.62 | E30: =E28+E29 -> 52619.544 | F30: =SUM(B30:E30) -> 24211.064
A31: Cumulative cash | B31: =B30 -> -74496.4 | C31: =B31+C30 -> -61053.1 | D31: =C31+D30 -> -28408.48 | E31: =D31+E30 -> 24211.064
A32: Break-even year | B32: =IF(C31>=0,"Year 1",IF(D31>=0,"Year 2",IF(E31>=0,"Year 3","After Year 3"))) -> Year 3
A33: ROI after 3 years (cumulative cash ÷ budget) | B33: =IF('Development Cost'!$F$26=0,0,E31/'Development Cost'!$F$26) -> 0.32499643
A34: NPV of 3 years (at discount rate) | B34: =B30+NPV(Assumptions!$D$17,C30:E30) -> 984.1897
A36: HIGH SCENARIO | B36: Year 0 (dev) | C36: Year 1 | D36: Year 2 | E36: Year 3 | F36: Total
A37: Net revenue | B37: 0 | C37: =Revenue!C44 -> 144609.38 | D37: =Revenue!D44 -> 279585.94 | E37: =Revenue!E44 -> 452980.31 | F37: =SUM(B37:E37) -> 877175.62
A38: Development & launch cost | B38: =-'Development Cost'!$F$26 -> -74496.4 | C38: 0 | D38: 0 | E38: 0 | F38: =SUM(B38:E38) -> -74496.4
A39: Live-ops & new scenario packs | B39: 0 | C39: =-Assumptions!$D$12 -> -12000 | D39: =-Assumptions!$D$12 -> -12000 | E39: =-Assumptions!$D$12 -> -12000 | F39: =SUM(B39:E39) -> -36000
A40: Ongoing marketing | B40: 0 | C40: =-Assumptions!$D$13 -> -6000 | D40: =-Assumptions!$D$13 -> -6000 | E40: =-Assumptions!$D$13 -> -6000 | F40: =SUM(B40:E40) -> -18000
A41: Hosting, tools, store accounts | B41: 0 | C41: =-Assumptions!$D$14 -> -600 | D41: =-Assumptions!$D$14 -> -600 | E41: =-Assumptions!$D$14 -> -600 | F41: =SUM(B41:E41) -> -1800
A42: B2B customer support | B42: 0 | C42: =-Revenue!C39*Assumptions!$D$15 -> -2250 | D42: =-Revenue!D39*Assumptions!$D$15 -> -5700 | E42: =-Revenue!E39*Assumptions!$D$15 -> -11400 | F42: =SUM(B42:E42) -> -19350
A43: TOTAL COSTS | B43: =SUM(B38:B42) -> -74496.4 | C43: =SUM(C38:C42) -> -20850 | D43: =SUM(D38:D42) -> -24300 | E43: =SUM(E38:E42) -> -30000 | F43: =SUM(B43:E43) -> -149646.4
...

Sheet Market Estimation
A1: Market Estimation — TAM / SAM / SOM (bottom-up)
A2: Approximate public figures — verify and add the source link before submitting.
A4: Consumer market (players) | B4: Value | C4: Note / source
A5: Young people 16–26 in main English-speaking markets (US, UK, CA, AU) | B5: 70000000 | C5: Approx. from national census data — verify
A6: Share who play mobile/web games | B6: 0.75 | C6: Assumption based on industry surveys — verify
A7: TAM — players | B7: =B5*B6 -> 52500000 | C7: Formula: population × share
A8: Share interested in life-sim / educational / money games | B8: 0.1 | C8: Assumption
A9: SAM — players | B9: =B7*B8 -> 5250000 | C9: Formula: TAM × share
A10: Share we can reach in Year 1 with a $75k budget | B10: 0.023 | C10: Assumption — calibrated to Base scenario
A11: SOM — players in Year 1 | B11: =B9*B10 -> 120750 | C11: Formula: SAM × share; compare with Assumptions → Players Y1 (Base)
A12: Base-scenario Players Y1 (from Assumptions) | B12: =Assumptions!$D$20 -> 120000
A14: B2B market (institutions) | B14: Value | C14: Note / source
A15: US public high schools | B15: 24000 | C15: NCES: ≈ 24k public high schools — verify
A16: US credit unions | B16: 4500 | C16: NCUA: ≈ 4.5k federally insured credit unions — verify
A17: Employers with financial-wellness programs (target list) | B17: 2000 | C17: Assumption: mid-size US employers
A18: TAM — institutions | B18: =SUM(B15:B17) -> 30500
A19: TAM — value per year (× Base license price) | B19: =B18*Assumptions!$D$29 -> 61000000
A20: Base-scenario licenses in Year 3 (SOM) | B20: =Revenue!E25 -> 26
A21: SOM as % of TAM institutions | B21: =IF(B18=0,0,B20/B18) -> 0.00085245902

Sheet Roadmap
A1: Roadmap — 9 months development + first year after launch
A2: Change Start month / Duration (blue); the timeline fills automatically.
A4: Phase | B4: Key deliverable / milestone | C4: Start month | D4: Duration (months) | E4: M1 | F4: M2 | G4: M3 | H4: M4 | I4: M5 | J4: M6 | K4: M7 | L4: M8 | M4: M9 | N4: M10 | O4: M11 | P4: M12 | Q4: M13 | R4: M14 | S4: M15
A5: Pre-production | B5: Concept, Macro GDD, economy model on paper | C5: 1 | D5: 2 | E5: =IF(AND(1>=$C5,1<$C5+$D5),"■","") -> ■ | F5: =IF(AND(2>=$C5,2<$C5+$D5),"■","") -> ■ | G5: =IF(AND(3>=$C5,3<$C5+$D5),"■","") | H5: =IF(AND(4>=$C5,4<$C5+$D5),"■","") | I5: =IF(AND(5>=$C5,5<$C5+$D5),"■","") | J5: =IF(AND(6>=$C5,6<$C5+$D5),"■","") | K5: =IF(AND(7>=$C5,7<$C5+$D5),"■","") | L5: =IF(AND(8>=$C5,8<$C5+$D5),"■","") | M5: =IF(AND(9>=$C5,9<$C5+$D5),"■","") | N5: =IF(AND(10>=$C5,10<$C5+$D5),"■","") | O5: =IF(AND(11>=$C5,11<$C5+$D5),"■","") | P5: =IF(AND(12>=$C5,12<$C5+$D5),"■","") | Q5: =IF(AND(13>=$C5,13<$C5+$D5),"■","") | R5: =IF(AND(14>=$C5,14<$C5+$D5),"■","") | S5: =IF(AND(15>=$C5,15<$C5+$D5),"■","")
A6: Vertical slice | B6: 1 full scenario playable (first job & rent) | C6: 3 | D6: 2 | E6: =IF(AND(1>=$C6,1<$C6+$D6),"■","") | F6: =IF(AND(2>=$C6,2<$C6+$D6),"■","") | G6: =IF(AND(3>=$C6,3<$C6+$D6),"■","") -> ■ | H6: =IF(AND(4>=$C6,4<$C6+$D6),"■","") -> ■ | I6: =IF(AND(5>=$C6,5<$C6+$D6),"■","") | J6: =IF(AND(6>=$C6,6<$C6+$D6),"■","") | K6: =IF(AND(7>=$C6,7<$C6+$D6),"■","") | L6: =IF(AND(8>=$C6,8<$C6+$D6),"■","") | M6: =IF(AND(9>=$C6,9<$C6+$D6),"■","") | N6: =IF(AND(10>=$C6,10<$C6+$D6),"■","") | O6: =IF(AND(11>=$C6,11<$C6+$D6),"■","") | P6: =IF(AND(12>=$C6,12<$C6+$D6),"■","") | Q6: =IF(AND(13>=$C6,13<$C6+$D6),"■","") | R6: =IF(AND(14>=$C6,14<$C6+$D6),"■","") | S6: =IF(AND(15>=$C6,15<$C6+$D6),"■","")
A7: Content production | B7: Core game: 10–12 life scenarios, art, UI | C7: 5 | D7: 3 | E7: =IF(AND(1>=$C7,1<$C7+$D7),"■","") | F7: =IF(AND(2>=$C7,2<$C7+$D7),"■","") | G7: =IF(AND(3>=$C7,3<$C7+$D7),"■","") | H7: =IF(AND(4>=$C7,4<$C7+$D7),"■","") | I7: =IF(AND(5>=$C7,5<$C7+$D7),"■","") -> ■ | J7: =IF(AND(6>=$C7,6<$C7+$D7),"■","") -> ■ | K7: =IF(AND(7>=$C7,7<$C7+$D7),"■","") -> ■ | L7: =IF(AND(8>=$C7,8<$C7+$D7),"■","") | M7: =IF(AND(9>=$C7,9<$C7+$D7),"■","") | N7: =IF(AND(10>=$C7,10<$C7+$D7),"■","") | O7: =IF(AND(11>=$C7,11<$C7+$D7),"■","") | P7: =IF(AND(12>=$C7,12<$C7+$D7),"■","") | Q7: =IF(AND(13>=$C7,13<$C7+$D7),"■","") | R7: =IF(AND(14>=$C7,14<$C7+$D7),"■","") | S7: =IF(AND(15>=$C7,15<$C7+$D7),"■","")
A8: Beta + school pilot | B8: Closed beta, 2–3 pilot classrooms, finance-expert review | C8: 8 | D8: 1 | E8: =IF(AND(1>=$C8,1<$C8+$D8),"■","") | F8: =IF(AND(2>=$C8,2<$C8+$D8),"■","") | G8: =IF(AND(3>=$C8,3<$C8+$D8),"■","") | H8: =IF(AND(4>=$C8,4<$C8+$D8),"■","") | I8: =IF(AND(5>=$C8,5<$C8+$D8),"■","") | J8: =IF(AND(6>=$C8,6<$C8+$D8),"■","") | K8: =IF(AND(7>=$C8,7<$C8+$D8),"■","") | L8: =IF(AND(8>=$C8,8<$C8+$D8),"■","") -> ■ | M8: =IF(AND(9>=$C8,9<$C8+$D8),"■","") | N8: =IF(AND(10>=$C8,10<$C8+$D8),"■","") | O8: =IF(AND(11>=$C8,11<$C8+$D8),"■","") | P8: =IF(AND(12>=$C8,12<$C8+$D8),"■","") | Q8: =IF(AND(13>=$C8,13<$C8+$D8),"■","") | R8: =IF(AND(14>=$C8,14<$C8+$D8),"■","") | S8: =IF(AND(15>=$C8,15<$C8+$D8),"■","")
A9: LAUNCH | B9: Web (itch.io + portals) and iOS/Android release | C9: 9 | D9: 1 | E9: =IF(AND(1>=$C9,1<$C9+$D9),"■","") | F9: =IF(AND(2>=$C9,2<$C9+$D9),"■","") | G9: =IF(AND(3>=$C9,3<$C9+$D9),"■","") | H9: =IF(AND(4>=$C9,4<$C9+$D9),"■","") | I9: =IF(AND(5>=$C9,5<$C9+$D9),"■","") | J9: =IF(AND(6>=$C9,6<$C9+$D9),"■","") | K9: =IF(AND(7>=$C9,7<$C9+$D9),"■","") | L9: =IF(AND(8>=$C9,8<$C9+$D9),"■","") | M9: =IF(AND(9>=$C9,9<$C9+$D9),"■","") -> ■ | N9: =IF(AND(10>=$C9,10<$C9+$D9),"■","") | O9: =IF(AND(11>=$C9,11<$C9+$D9),"■","") | P9: =IF(AND(12>=$C9,12<$C9+$D9),"■","") | Q9: =IF(AND(13>=$C9,13<$C9+$D9),"■","") | R9: =IF(AND(14>=$C9,14<$C9+$D9),"■","") | S9: =IF(AND(15>=$C9,15<$C9+$D9),"■","")
A10: Marketing campaign | B10: 'Make your mistakes here' — creators + short video | C10: 8 | D10: 3 | E10: =IF(AND(1>=$C10,1<$C10+$D10),"■","") | F10: =IF(AND(2>=$C10,2<$C10+$D10),"■","") | G10: =IF(AND(3>=$C10,3<$C10+$D10),"■","") | H10: =IF(AND(4>=$C10,4<$C10+$D10),"■","") | I10: =IF(AND(5>=$C10,5<$C10+$D10),"■","") | J10: =IF(AND(6>=$C10,6<$C10+$D10),"■","") | K10: =IF(AND(7>=$C10,7<$C10+$D10),"■","") | L10: =IF(AND(8>=$C10,8<$C10+$D10),"■","") -> ■ | M10: =IF(AND(9>=$C10,9<$C10+$D10),"■","") -> ■ | N10: =IF(AND(10>=$C10,10<$C10+$D10),"■","") -> ■ | O10: =IF(AND(11>=$C10,11<$C10+$D10),"■","") | P10: =IF(AND(12>=$C10,12<$C10+$D10),"■","") | Q10: =IF(AND(13>=$C10,13<$C10+$D10),"■","") | R10: =IF(AND(14>=$C10,14<$C10+$D10),"■","") | S10: =IF(AND(15>=$C10,15<$C10+$D10),"■","")
A11: Scenario pack #1–2 | B11: Credit card & investing packs (IAP) | C11: 10 | D11: 3 | E11: =IF(AND(1>=$C11,1<$C11+$D11),"■","") | F11: =IF(AND(2>=$C11,2<$C11+$D11),"■","") | G11: =IF(AND(3>=$C11,3<$C11+$D11),"■","") | H11: =IF(AND(4>=$C11,4<$C11+$D11),"■","") | I11: =IF(AND(5>=$C11,5<$C11+$D11),"■","") | J11: =IF(AND(6>=$C11,6<$C11+$D11),"■","") | K11: =IF(AND(7>=$C11,7<$C11+$D11),"■","") | L11: =IF(AND(8>=$C11,8<$C11+$D11),"■","") | M11: =IF(AND(9>=$C11,9<$C11+$D11),"■","") | N11: =IF(AND(10>=$C11,10<$C11+$D11),"■","") -> ■ | O11: =IF(AND(11>=$C11,11<$C11+$D11),"■","") -> ■ | P11: =IF(AND(12>=$C11,12<$C11+$D11),"■","") -> ■ | Q11: =IF(AND(13>=$C11,13<$C11+$D11),"■","") | R11: =IF(AND(14>=$C11,14<$C11+$D11),"■","") | S11: =IF(AND(15>=$C11,15<$C11+$D11),"■","")
A12: B2B sales | B12: Teacher guide, outreach to schools / credit unions | C12: 9 | D12: 7 | E12: =IF(AND(1>=$C12,1<$C12+$D12),"■","") | F12: =IF(AND(2>=$C12,2<$C12+$D12),"■","") | G12: =IF(AND(3>=$C12,3<$C12+$D12),"■","") | H12: =IF(AND(4>=$C12,4<$C12+$D12),"■","") | I12: =IF(AND(5>=$C12,5<$C12+$D12),"■","") | J12: =IF(AND(6>=$C12,6<$C12+$D12),"■","") | K12: =IF(AND(7>=$C12,7<$C12+$D12),"■","") | L12: =IF(AND(8>=$C12,8<$C12+$D12),"■","") | M12: =IF(AND(9>=$C12,9<$C12+$D12),"■","") -> ■ | N12: =IF(AND(10>=$C12,10<$C12+$D12),"■","") -> ■ | O12: =IF(AND(11>=$C12,11<$C12+$D12),"■","") -> ■ | P12: =IF(AND(12>=$C12,12<$C12+$D12),"■","") -> ■ | Q12: =IF(AND(13>=$C12,13<$C12+$D12),"■","") -> ■ | R12: =IF(AND(14>=$C12,14<$C12+$D12),"■","") -> ■ | S12: =IF(AND(15>=$C12,15<$C12+$D12),"■","") -> ■
A13: Scenario pack #3–4 | B13: First home & job loss packs | C13: 13 | D13: 3 | E13: =IF(AND(1>=$C13,1<$C13+$D13),"■","") | F13: =IF(AND(2>=$C13,2<$C13+$D13),"■","") | G13: =IF(AND(3>=$C13,3<$C13+$D13),"■","") | H13: =IF(AND(4>=$C13,4<$C13+$D13),"■","") | I13: =IF(AND(5>=$C13,5<$C13+$D13),"■","") | J13: =IF(AND(6>=$C13,6<$C13+$D13),"■","") | K13: =IF(AND(7>=$C13,7<$C13+$D13),"■","") | L13: =IF(AND(8>=$C13,8<$C13+$D13),"■","") | M13: =IF(AND(9>=$C13,9<$C13+$D13),"■","") | N13: =IF(AND(10>=$C13,10<$C13+$D13),"■","") | O13: =IF(AND(11>=$C13,11<$C13+$D13),"■","") | P13: =IF(AND(12>=$C13,12<$C13+$D13),"■","") | Q13: =IF(AND(13>=$C13,13<$C13+$D13),"■","") -> ■ | R13: =IF(AND(14>=$C13,14<$C13+$D13),"■","") -> ■ | S13: =IF(AND(15>=$C13,15<$C13+$D13),"■","") -> ■

Sheet Comparable Games
A1: Reference games on itch.io (NOT on Steam) — for 'The Game (Link)' column
A2: Fill the yellow cells from each itch.io page (rating, number of ratings, comments) before the pitch.
A4: Game | B4: Developer | C4: Link | D4: Platform | E4: Price model | F4: Rating (fill) | G4: # ratings (fill) | H4: What it does | I4: Relevance to MoneyWise
A5: Your Financial Story | B5: Brogan M. Pratt | C5: https://brogan-m-pratt.itch.io/yourfinancialstory | D5: Windows, macOS, Linux, Android | E5: Paid, ≈ $3.94 CAD or more | H5: Personal finance game: pick a career, survive life events, learn zero-sum budgeting | I5: ★ RECOMMENDED main reference: same idea (life choices → money consequences), proves people pay for it
A6: Eviction Notice | B6: Almost Safe Studio | C6: https://almost-safe-studio.itch.io/eviction-notice | D6: Browser | E6: Free (check page) | H6: Real-time cashflow survival sim: rent, side gigs, stress, buying property | I6: Shows browser format + dramatic 'money pressure' works as entertainment
A7: Chengetedzo | B7: baba.zw | C7: https://babazw.itch.io/chengetedzo | D7: Browser / download (check) | E7: Free (check page) | H7: Household budget over 24 months: income, savings, insurance, loans (Zimbabwe, 9+) | I7: Closest edu-sim loop (monthly decisions); shows localization opportunity
A8: Money Games & Budget Simulator | B8: Nullexe Games | C8: https://nullexa.itch.io/money-games-budget-simulator | D8: Browser | E8: Free | H8: Short budgeting challenges, part of a personal-finance education brand | I8: Example of game as funnel for a finance-education business (B2B/brand angle)
A9: Simufy | B9: Richies Huynh | C9: https://burningicicles.itch.io/simufy | D9: Check page | E9: Check page | H9: Young adult / mid-career life sim: health, money, retirement | I9: Similar target audience (young adults, first job)
A10: Gainz: The Financial Literacy Game | B10: bbutterscotch | C10: https://bbutterscotch.itch.io/gainz | D10: Check page | E10: Check page | H10: Tinder-like swipe decisions about money | I10: Idea for fast, mobile-friendly decision UI
A12: Excluded: 'Life & Debt: A Real Life Simulator' — also sold on Steam (itch.io purchase gives a Steam key).

Sheet How to use
A1: How to use this model
A2: 1. Change inputs only on 'Assumptions' (blue text) and 'Development Cost' (blue text). Everything else recalculates.
A3: 2. Yellow cells are the key assumptions — be ready to explain them in the pitch.
A4: 3. 'Summary' has the numbers for the Pitchdeck slides: Price / Gross Revenue, Market Estimation, Targets, Development Cost.
A5: 4. 'Market Estimation' figures are approximate — add source links before submitting.
A6: 5. 'Comparable Games' — fill rating and number of ratings from each itch.io page.
A8: Colour code: blue = input · black = formula · green = link to another sheet · yellow fill = key assumption
A9: Example input row: Assumptions → 'Paying conversion' Low 1.5% / Base 3.0% / High 5.0% (type 3% or 0.03).
